Workbook
Name _DAT1: #REF!
Name _DAT1: #REF!
Name _DAT1: #REF!
Name _DAT10: #REF!
Name _DAT10: #REF!
Name _dat105: #REF!
Name _dat105: #REF!
Name _DAT11: #REF!
Name _DAT11: #REF!
Name _DAT12: #REF!
Name _DAT12: #REF!
Name _DAT13: #REF!
Name _DAT13: #REF!
Name _DAT14: #REF!
Name _DAT14: #REF!
Name _DAT15: #REF!
Name _DAT15: #REF!
Name _DAT16: #REF!
Name _DAT16: #REF!
Name _DAT17: #REF!
Name _DAT17: #REF!
Name _DAT18: #REF!
Name _DAT18: #REF!
Name _DAT19: #REF!
Name _DAT19: #REF!
Name _DAT2: #REF!
Name _DAT2: #REF!
Name _DAT20: #REF!
Name _DAT20: #REF!
Name _DAT3: #REF!
Name _DAT3: #REF!
Name _DAT4: #REF!
Name _DAT4: #REF!
Name _DAT5: #REF!
Name _DAT5: #REF!
Name _DAT6: #REF!
Name _DAT6: #REF!
Name _DAT7: #REF!
Name _DAT7: #REF!
Name _DAT8: #REF!
Name _DAT8: #REF!
Name _DAT9: #REF!
Name _DAT9: #REF!
Name ACUMULACAO: #REF!
Name ACUMULACAO: #REF!
Name Administrativo: #REF!
Name Administrativo: #REF!
Name Format2Print: #REF!
Name IDCARGO: #REF!
Name IDCARGO: #REF!
Name IDCARGO: #REF!
Name NP: #REF!
Name NP: #REF!
Name QP: #REF!
Name QP: #REF!
Name TABMOL: #REF!
Name TABMOL: #REF!
Name TEST1: #REF!
Name TEST1: #REF!
Name TEST2: #REF!

Sheet Corporativo
B1: Operacional | D1: Apoio | F1: Comprador e Controlador de Manutenção | H1: Analista | J1: Encarregado e Supervisor | L1: Gerente | N1: Diretor
B2: Competências | C2: Peso | D2: Competências | E2: Peso | F2: Competências | G2: Peso | H2: Competências | I2: Peso | J2: Competências | K2: Peso | L2: Competências | M2: Peso | N2: Competências | O2: Peso
A3: 1 | B3: Comprometimento | C3: 0.25 | D3: Comprometimento | E3: 0.2 | F3: Comprometimento | G3: 0.2 | H3: Comprometimento | I3: 0.1 | J3: Comprometimento | K3: 0.15 | L3: Comprometimento | M3: 0.15 | N3: Comprometimento | O3: 0.1
A4: 2 | B4: Organização e zelo com equipamentos | C4: 0.2 | D4: Disciplina | E4: 0.2 | F4: Capacidade de análise | G4: 0.15 | H4: Atenção | I4: 0.2 | J4: Eficiência | K4: 0.15 | L4: Gestão de Pessoas | M4: 0.25 | N4: Gestão de Pessoas | O4: 0.2
A5: 3 | B5: Orientação para segurança | C5: 0.15 | D5: Organização e zelo com equipamentos | E5: 0.15 | F5: Negociação | G5: 0.25 | H5: Capacidade de análise | I5: 0.2 | J5: Gestão de Pessoas | K5: 0.2 | L5: Orientação para resultados | M5: 0.25 | N5: Gestão de recursos | O5: 0.25
A6: 4 | B6: Proatividade | C6: 0.2 | D6: Orientação para segurança | E6: 0.1 | F6: Planejamento | G6: 0.25 | H6: Planejamento | I6: 0.2 | J6: Orientação para resultados | K6: 0.2 | L6: Tomada de decisão | M6: 0.25 | N6: Relacionamento interpessoal | O6: 0.1
A7: 5 | B7: Trabalho em equipe | C7: 0.2 | D7: Proatividade | E7: 0.15 | F7: Trabalho em equipe | G7: 0.15 | H7: Qualidade | I7: 0.15 | J7: Tomada de decisão | K7: 0.2 | L7: Visão estratégica | M7: 0.1 | N7: Resiliência | O7: 0.1
A8: 6 | D8: Trabalho em equipe | E8: 0.2 | H8: Trabalho em equipe | I8: 0.15 | J8: Visão sistêmica | K8: 0.1 | N8: Visão estratégica | O8: 0.25
A9: 7
A10: 8
A11: 9
A12: 10
B13: Soma | C13: =SUM(C3:C12) -> 1 | D13: Soma | E13: =SUM(E3:E12) -> 1 | F13: Soma | G13: =SUM(G3:G12) -> 1 | H13: Soma | I13: =SUM(I3:I12) -> 1 | J13: Soma | K13: =SUM(K3:K12) -> 1 | L13: Soma | M13: =SUM(M3:M12) -> 1 | N13: Soma | O13: =SUM(O3:O12) -> 1

Sheet Operacional
A2: Grupo funcional: Operacional | D2: Peso total | E2: Pontuação
D3: =SUM(C7,C15,C23,C31,C39) -> 1 | E3: =SUM(E7,E15,E23,E31,E39) -> 0
D4: Resultado
A5: =Corporativo!B3 -> Comprometimento | B5: Avaliação | D5: =IF(E3<=[1]Referências!$B$9,[1]Referências!C9,IF(E3<=[1]Referências!$B$10,[1]Referências!$C$10,IF(E3<=[1]Referências!$B$11,[1]Referências!$C$11,IF(E3<=[1]Referências!$B$12,[1]Referências!$C$12,[1]Referências!$C$13)))) -> Não atende
A6: Capacidade de cumprir as tarefas conforme normas, procedimentos e prazos estabelecidos, demonstrando constância, pontualidade, assiduidade e responsabilidade
A7: Comportamentos observáveis | C7: =VLOOKUP(A5,Corporativo!$B$3:$C$12,2,FALSE) -> 0.25 | E7: =C7*E12 -> 0
A8: Cumpre as tarefas quando solicitado, mas com frequência precisa de lembretes ou orientações para seguir normas e procedimentos, além disso apresenta dificuldades em manter a assiduidade e a pontualidade, tanto nas entregas quanto no cumprimento de horários | C8: =COUNTA(B8) -> 0 | D8: =Referências!$B$2 -> 1 | E8: =C8*D8 -> 0
A9: Cumpre as tarefas de forma regular, apresentando pontualidade e assiduidade e seguindo as normas e procedimentos estabelecidos na maior parte das vezes, mas ainda requer acompanhamento | C9: =COUNTA(B9) -> 0 | D9: =Referências!$B$3 -> 2 | E9: =C9*D9 -> 0
A10: Cumpre as tarefas de maneira constante e comprometida, com aderência às normas, procedimentos e padrões, demonstrando responsabilidade, assiduidade e pontualidade tanto nas entregas quanto no cumprimento de horários | C10: =COUNTA(B10) -> 0 | D10: =Referências!$B$4 -> 3 | E10: =C10*D10 -> 0
A11: Realiza as tarefas de forma exemplar, atuando como modelo de compromisso e responsabilidade, influenciando positivamente os outros ao demonstrar constância, pontualidade e responsabilidade em todas as entregas | C11: =COUNTA(B11) -> 0 | D11: =Referências!$B$5 -> 5 | E11: =C11*D11 -> 0
E12: =SUM(E8:E11) -> 0
A13: =Corporativo!B4 -> Organização e zelo com equipamentos | B13: Avaliação
A14: Realiza suas atribuições de forma ordenada, facilitando e contribuindo para a continuidade e sequência do trabalho, apresentando cuidado na utilização de bens, equipamentos e materiais da empresa
A15: Comportamentos observáveis | C15: =VLOOKUP(A13,Corporativo!$B$3:$C$12,2,FALSE) -> 0.2 | D15: =COUNTA(A17:A19) -> 3 | E15: =C15*E20 -> 0
A16: O trabalho não é realizado de forma ordenada, reduzindo a produtividade e dificultando a sequência do trabalho por outra pessoa quando necessário, e não zela pela conservação dos equipamentos e materiais sob sua responsabilidade | C16: =COUNTA(B16) -> 0 | D16: =Referências!$B$2 -> 1 | E16: =C16*D16 -> 0
A17: Esforça-se para organizar adequadamente o trabalho e cuidar dos materiais e equipamentos sob sua responsabilidade, mas ainda necessita de orientação e apoio | C17: =COUNTA(B17) -> 0 | D17: =Referências!$B$3 -> 2 | E17: =C17*D17 -> 0
A18: Mantem organizado o seu ambiente de trabalho, planejando suas tarefas sem necessidade de apoio e mantém organizado o ambiente de trabalho e os materiais e equipamentos sob sua responsabilidade | C18: =COUNTA(B18) -> 0 | D18: =Referências!$B$4 -> 3 | E18: =C18*D18 -> 0
A19: Além da elevada organização, antecipa o que precisa ser feito, demonstra flexibilidade em resposta a prioridades e novas solicitações e antecipa o cumprimento de prazos. Materiais e equipamentos sob sua responsabilidade estão sempre com a manutenção em dia, adequadamente conservados e bem organizados. | C19: =COUNTA(B19) -> 0 | D19: =Referências!$B$5 -> 5 | E19: =C19*D19 -> 0
E20: =SUM(E16:E19) -> 0
A21: =Corporativo!B5 -> Orientação para segurança | B21: Avaliação
A22: Capacidade de priorizar a integridade física no ambiente de trabalho, seguindo normas, identificando riscos e adotando comportamentos preventivos para evitar acidentes, envolvendo uma postura ativa na promoção de um ambiente seguro para si e para os demais.
A23: Comportamentos observáveis | C23: =VLOOKUP(A21,Corporativo!$B$3:$C$12,2,FALSE) -> 0.15 | D23: =COUNTA(A24:A27) -> 4 | E23: =C23*E28 -> 0
A24: Segue as normas de segurança apenas quando exigido, age de forma reativa diante de riscos e não se preocupa em identificar ou relatar potenciais perigos no ambiente de trabalho | C24: =COUNTA(B24) -> 0 | D24: =Referências!$B$2 -> 1 | E24: =C24*D24 -> 0
A25: Adota práticas seguras no dia a dia, respeita normas e sinaliza riscos quando identificados, mas não age proativamente para promover a segurança de forma ampla | C25: =COUNTA(B25) -> 0 | D25: =Referências!$B$3 -> 2 | E25: =C25*D25 -> 0
A26: Além de cumprir as normas, antecipa e reporta riscos, orienta colegas sobre práticas seguras e busca melhorar processos para reduzir acidentes e incidentes | C26: =COUNTA(B26) -> 0 | D26: =Referências!$B$4 -> 3 | E26: =C26*D26 -> 0
A27: Atua como referência em segurança, inspira e orienta os outros, propõe e participa ativamente da implementação de melhorias nos procedimentos e age antecipadamente para eliminar riscos, contribuindo para um ambiente de trabalho mais seguro e preventivo | C27: =COUNTA(B27) -> 0 | D27: =Referências!$B$5 -> 5 | E27: =C27*D27 -> 0
E28: =SUM(E24:E27) -> 0
A29: =Corporativo!B6 -> Proatividade | B29: Avaliação
A30: Capacidade de agir de forma antecipada para evitar problemas e melhorar processos, atuando com iniciativa e atenção aos detalhes.
A31: Comportamentos observáveis | C31: =VLOOKUP(A29,Corporativo!$B$3:$C$12,2,FALSE) -> 0.2 | D31: =COUNTA(A32:A35) -> 4 | E31: =C31*E36 -> 0
A32: Atua apenas quando solicitado, aguarda instruções para iniciar qualquer atividade e não demonstra preocupação em antecipar problemas ou propor melhorias | C32: =COUNTA(B32) -> 0 | D32: =Referências!$B$2 -> 1 | E32: =C32*D32 -> 0
A33: Cumpre suas funções com qualidade e dentro dos prazos, sinaliza problemas à liderança, mas não busca soluções por conta própria, e participa de iniciativas de melhoria somente quando solicitado | C33: =COUNTA(B33) -> 0 | D33: =Referências!$B$3 -> 2 | E33: =C33*D33 -> 0
A34: Identifica problemas e propõe soluções antes que impactem o trabalho, busca melhorias para sua rotina e compartilha boas práticas, além de apoiar colegas quando percebe dificuldades | C34: =COUNTA(B34) -> 0 | D34: =Referências!$B$4 -> 3 | E34: =C34*D34 -> 0
A35: Atua como referência para a equipe, inspira colegas a serem mais proativos, antecipa falhas, propõe e participa ativamente da implementação de melhorias | C35: =COUNTA(B35) -> 0 | D35: =Referências!$B$5 -> 5 | E35: =C35*D35 -> 0
E36: =SUM(E32:E35) -> 0
A37: =Corporativo!B7 -> Trabalho em equipe | B37: Avaliação
A38: Capacidade de atuar de forma integrada, colaborando com os demais membros da equipe e cultivando relações respeitosas que promovam um ambiente harmonioso e impulsionem o alcance dos objetivos comuns
A39: Comportamentos observáveis | C39: =VLOOKUP(A37,Corporativo!$B$3:$C$12,2,FALSE) -> 0.2 | D39: =COUNTA(A40:A43) -> 4 | E39: =C39*E44 -> 0
A40: Participa das atividades em equipe quando solicitado, sem demonstrar proatividade, e apresenta dificuldades em manter interações respeitosas e harmoniosas | C40: =COUNTA(B40) -> 0 | D40: =Referências!$B$2 -> 1 | E40: =C40*D40 -> 0
A41: Demonstra maior engajamento na colaboração com a equipe, buscando alinhar esforços e ouvir diferentes opiniões com respeito, mas ainda sem consistência, necessitando de constante orientação por parte da supervisão | C41: =COUNTA(B41) -> 0 | D41: =Referências!$B$3 -> 2 | E41: =C41*D41 -> 0
...

Sheet Apoio
A2: Grupo funcional: Apoio | D2: Peso total | E2: Pontuação
D3: =SUM(C7,C15,C23,C31,C39,C47) -> 1 | E3: =SUM(E7,E15,E23,E31,E39,E47) -> 0
D4: Resultado
A5: =Corporativo!D3 -> Comprometimento | B5: Avaliação | D5: =IF(E3<=[1]Referências!$B$9,[1]Referências!C9,IF(E3<=[1]Referências!$B$10,[1]Referências!$C$10,IF(E3<=[1]Referências!$B$11,[1]Referências!$C$11,IF(E3<=[1]Referências!$B$12,[1]Referências!$C$12,[1]Referências!$C$13)))) -> Não atende
A6: Capacidade de cumprir as tarefas conforme normas e prazos estabelecidos, demonstrando constância, pontualidade, assiduidade e responsabilidade
A7: Comportamentos observáveis | C7: =VLOOKUP(A5,Corporativo!$D$3:$E$12,2,FALSE) -> 0.2 | E7: =C7*E12 -> 0
A8: Cumpre as tarefas quando solicitado, mas com frequência precisa de lembretes ou orientações para seguir normas, além disso apresenta dificuldades em manter a assiduidade e a pontualidade, tanto nas entregas quanto no cumprimento de horários | C8: =COUNTA(B8) -> 0 | D8: =Referências!$B$2 -> 1 | E8: =C8*D8 -> 0
A9: Cumpre as tarefas de forma regular, apresentando pontualidade e assiduidade e seguindo as normas estabelecidas na maior parte das vezes, mas ainda requer acompanhamento | C9: =COUNTA(B9) -> 0 | D9: =Referências!$B$3 -> 2 | E9: =C9*D9 -> 0
A10: Cumpre as tarefas de maneira constante e comprometida, com aderência às normas e padrões, demonstrando responsabilidade, assiduidade e pontualidade tanto nas entregas quanto no cumprimento de horários | C10: =COUNTA(B10) -> 0 | D10: =Referências!$B$4 -> 3 | E10: =C10*D10 -> 0
A11: Realiza as tarefas de forma exemplar, atuando como modelo de compromisso e responsabilidade, influenciando positivamente os outros ao demonstrar constância, pontualidade e responsabilidade em todas as entregas | C11: =COUNTA(B11) -> 0 | D11: =Referências!$B$5 -> 5 | E11: =C11*D11 -> 0
E12: =SUM(E8:E11) -> 0
A13: =Corporativo!D4 -> Disciplina | B13: Avaliação
A14: Capacidade de cumprir as atividades conforme orientações e procedimentos da empresa, respeitando os parâmetros de qualidade estabelecidos e garantindo a eficácia dos processos executados
A15: Comportamentos observáveis | C15: =VLOOKUP(A13,Corporativo!$D$3:$E$12,2,FALSE) -> 0.2 | D15: =COUNTA(A17:A19) -> 3 | E15: =C15*E20 -> 0
A16: Frequentemente deixa de cumprir orientações e procedimentos da empresa, impactando negativamente na qualidade do trabalho e nos resultados dos processos, necessitando ser advertido formalmente. | C16: =COUNTA(B16) -> 0 | D16: =Referências!$B$2 -> 1 | E16: =C16*D16 -> 0
A17: Quando orientado especificamente sobre um assunto age conforme as orientações, mas não demonstra empenho em cumprir os procedimentos de forma proativa, necessitando de supervisão direta. | C17: =COUNTA(B17) -> 0 | D17: =Referências!$B$3 -> 2 | E17: =C17*D17 -> 0
A18: Conhece os procedimentos e executa suas atividades em conformidade com eles, demonstrando empenho em contribuir para a eficácia dos processos. | C18: =COUNTA(B18) -> 0 | D18: =Referências!$B$4 -> 3 | E18: =C18*D18 -> 0
A19: Conhece os procedimentos e executa suas atividades em conformidade com eles, apoiando outras pessoas na execução do trabalho, demonstrando empenho em ampliar seus conhecimentos e em contribuir com a eficácia dos processos. | C19: =COUNTA(B19) -> 0 | D19: =Referências!$B$5 -> 5 | E19: =C19*D19 -> 0
E20: =SUM(E16:E19) -> 0
A21: =Corporativo!D5 -> Organização e zelo com equipamentos | B21: Avaliação
A22: Realiza suas atribuições de forma ordenada, facilitando e contribuindo para a continuidade e sequência do trabalho, apresentando cuidado na utilização de bens, equipamentos e materiais da empresa
A23: Comportamentos observáveis | C23: =VLOOKUP(A21,Corporativo!$D$3:$E$12,2,FALSE) -> 0.15 | D23: =COUNTA(A24:A27) -> 4 | E23: =C23*E28 -> 0
A24: O trabalho não é realizado de forma ordenada, reduzindo a produtividade e dificultando a sequência do trabalho por outra pessoa quando necessário, e não zela pela conservação dos equipamentos e materiais sob sua responsabilidade | C24: =COUNTA(B24) -> 0 | D24: =Referências!$B$2 -> 1 | E24: =C24*D24 -> 0
A25: Esforça-se para organizar adequadamente o trabalho e cuidar dos materiais e equipamentos sob sua responsabilidade, mas ainda necessita de orientação e apoio | C25: =COUNTA(B25) -> 0 | D25: =Referências!$B$3 -> 2 | E25: =C25*D25 -> 0
A26: Mantem organizado o seu ambiente de trabalho, planejando suas tarefas sem necessidade de apoio e mantém organizado o ambiente de trabalho e os materiais e equipamentos sob sua responsabilidade | C26: =COUNTA(B26) -> 0 | D26: =Referências!$B$4 -> 3 | E26: =C26*D26 -> 0
A27: Além da elevada organização, antecipa o que precisa ser feito, demonstra flexibilidade em resposta a prioridades e novas solicitações e antecipa o cumprimento de prazos. Materiais e equipamentos sob sua responsabilidade estão sempre com a manutenção em dia, adequadamente conservados e bem organizados. | C27: =COUNTA(B27) -> 0 | D27: =Referências!$B$5 -> 5 | E27: =C27*D27 -> 0
E28: =SUM(E24:E27) -> 0
A29: =Corporativo!D6 -> Orientação para segurança | B29: Avaliação
A30: Capacidade de priorizar a integridade física no ambiente de trabalho, seguindo normas, identificando riscos e adotando comportamentos preventivos para evitar acidentes, envolvendo uma postura ativa na promoção de um ambiente seguro para si e para os demais.
A31: Comportamentos observáveis | C31: =VLOOKUP(A29,Corporativo!$D$3:$E$12,2,FALSE) -> 0.1 | D31: =COUNTA(A32:A35) -> 4 | E31: =C31*E36 -> 0
A32: Segue as normas de segurança apenas quando exigido, age de forma reativa diante de riscos e não se preocupa em identificar ou relatar potenciais perigos no ambiente de trabalho | C32: =COUNTA(B32) -> 0 | D32: =Referências!$B$2 -> 1 | E32: =C32*D32 -> 0
A33: Adota práticas seguras no dia a dia, respeita normas e sinaliza riscos quando identificados, mas não age proativamente para promover a segurança de forma ampla | C33: =COUNTA(B33) -> 0 | D33: =Referências!$B$3 -> 2 | E33: =C33*D33 -> 0
A34: Além de cumprir as normas, antecipa e reporta riscos, orienta colegas sobre práticas seguras e busca melhorar processos para reduzir acidentes e incidentes | C34: =COUNTA(B34) -> 0 | D34: =Referências!$B$4 -> 3 | E34: =C34*D34 -> 0
A35: Atua como referência em segurança, inspira e orienta os outros, propõe e participa ativamente da implementação de melhorias nos procedimentos e age antecipadamente para eliminar riscos, contribuindo para um ambiente de trabalho mais seguro e preventivo | C35: =COUNTA(B35) -> 0 | D35: =Referências!$B$5 -> 5 | E35: =C35*D35 -> 0
E36: =SUM(E32:E35) -> 0
A37: =Corporativo!D7 -> Proatividade | B37: Avaliação
A38: Capacidade de agir de forma antecipada para evitar problemas e melhorar processos, atuando com iniciativa e atenção aos detalhes.
A39: Comportamentos observáveis | C39: =VLOOKUP(A37,Corporativo!$D$3:$E$12,2,FALSE) -> 0.15 | D39: =COUNTA(A40:A43) -> 4 | E39: =C39*E44 -> 0
A40: Atua apenas quando solicitado, aguarda instruções para iniciar qualquer atividade e não demonstra preocupação em antecipar problemas ou propor melhorias | C40: =COUNTA(B40) -> 0 | D40: =Referências!$B$2 -> 1 | E40: =C40*D40 -> 0
A41: Cumpre suas funções com qualidade e dentro dos prazos, sinaliza problemas à liderança, mas não busca soluções por conta própria, e participa de iniciativas de melhoria somente quando solicitado | C41: =COUNTA(B41) -> 0 | D41: =Referências!$B$3 -> 2 | E41: =C41*D41 -> 0
...

Sheet Comprador e Controlador Manut.
A2: Grupo funcional: Comprador e Controlador de Manutenção | D2: Peso total | E2: Pontuação
D3: =SUM(C7,C15,C23,C31,C39) -> 1 | E3: =SUM(E7,E15,E23,E31,E39) -> 0
D4: Resultado
A5: =Corporativo!F3 -> Comprometimento | B5: Avaliação | D5: =IF(E3<=[1]Referências!$B$9,[1]Referências!C9,IF(E3<=[1]Referências!$B$10,[1]Referências!$C$10,IF(E3<=[1]Referências!$B$11,[1]Referências!$C$11,IF(E3<=[1]Referências!$B$12,[1]Referências!$C$12,[1]Referências!$C$13)))) -> Não atende
A6: Capacidade de cumprir as tarefas conforme normas e prazos estabelecidos, demonstrando constância, pontualidade, assiduidade e responsabilidade
A7: Comportamentos observáveis | C7: =VLOOKUP(A5,Corporativo!$F$3:$G$12,2,FALSE) -> 0.2 | E7: =C7*E12 -> 0
A8: Cumpre as tarefas quando solicitado, mas com frequência precisa de lembretes ou orientações para seguir normas, além disso apresenta dificuldades em manter a assiduidade e a pontualidade, tanto nas entregas quanto no cumprimento de horários | C8: =COUNTA(B8) -> 0 | D8: =Referências!$B$2 -> 1 | E8: =C8*D8 -> 0
A9: Cumpre as tarefas de forma regular, apresentando pontualidade e assiduidade e seguindo as normas estabelecidas na maior parte das vezes, mas ainda requer acompanhamento | C9: =COUNTA(B9) -> 0 | D9: =Referências!$B$3 -> 2 | E9: =C9*D9 -> 0
A10: Cumpre as tarefas de maneira constante e comprometida, com aderência às normas e padrões, demonstrando responsabilidade, assiduidade e pontualidade tanto nas entregas quanto no cumprimento de horários | C10: =COUNTA(B10) -> 0 | D10: =Referências!$B$4 -> 3 | E10: =C10*D10 -> 0
A11: Realiza as tarefas de forma exemplar, atuando como modelo de compromisso e responsabilidade, influenciando positivamente os outros ao demonstrar constância, pontualidade e responsabilidade em todas as entregas | C11: =COUNTA(B11) -> 0 | D11: =Referências!$B$5 -> 5 | E11: =C11*D11 -> 0
E12: =SUM(E8:E11) -> 0
A13: =Corporativo!F4 -> Capacidade de análise | B13: Avaliação
A14: Capacidade de avaliar informações, situações ou resultados de maneira interpretativa e baseada em dados e argumentos sólidos, extraindo pontos relevantes, convergindo, construindo diagnósticos e apresentando alternativas e soluções eficazes
A15: Comportamentos observáveis | C15: =VLOOKUP(A13,Corporativo!$F$3:$G$12,2,FALSE) -> 0.15 | D15: =COUNTA(A17:A19) -> 3 | E15: =C15*E20 -> 0
A16: Avalia informações e situações de forma superficial, sem considerar dados e argumentos sólidos, frequentemente precisando de orientação para identificar pontos relevantes e extrair diagnósticos | C16: =COUNTA(B16) -> 0 | D16: =Referências!$B$2 -> 1 | E16: =C16*D16 -> 0
A17: Realiza avaliações mais fundamentadas, considerando dados e informações, mas ainda com dificuldade em convergir e sintetizar os pontos mais relevantes de maneira clara e concisa | C17: =COUNTA(B17) -> 0 | D17: =Referências!$B$3 -> 2 | E17: =C17*D17 -> 0
A18: Analisa informações e resultados de maneira interpretativa e organizada, utilizando dados e argumentos consistentes para elaborar diagnósticos claros e objetivos, extraindo os pontos mais relevantes de forma eficiente e apresentando alternativas e soluções eficazes | C18: =COUNTA(B18) -> 0 | D18: =Referências!$B$4 -> 3 | E18: =C18*D18 -> 0
A19: Realiza avaliações complexas e altamente interpretativas, extraindo ideias e construindo diagnósticos precisos, com base em dados robustos e argumentos bem fundamentados, apresentando alternativas e soluções eficazes | C19: =COUNTA(B19) -> 0 | D19: =Referências!$B$5 -> 5 | E19: =C19*D19 -> 0
E20: =SUM(E16:E19) -> 0
A21: =Corporativo!F5 -> Negociação | B21: Avaliação
A22: Capacidade de conduzir negociações de forma estruturada, explorando alternativas e controlando emoções para alcançar soluções justas e satisfatórias para todas as partes
A23: Comportamentos observáveis | C23: =VLOOKUP(A21,Corporativo!$F$3:$G$12,2,FALSE) -> 0.25 | D23: =COUNTA(A24:A27) -> 4 | E23: =C23*E28 -> 0
A24: Apresenta dificuldade em conduzir negociações de forma estruturada, geralmente reagindo às situações sem explorar alternativas e apresentando dificuldades para controlar as emoções, o que pode resultar em soluções insatisfatórias | C24: =COUNTA(B24) -> 0 | D24: =Referências!$B$2 -> 1 | E24: =C24*D24 -> 0
A25: Conduz negociações de forma razoavelmente estruturada, considerando algumas alternativas, mas ainda pode ter dificuldades em controlar emoções em situações de tensão, o que impacta a busca por soluções justas para todas as partes | C25: =COUNTA(B25) -> 0 | D25: =Referências!$B$3 -> 2 | E25: =C25*D25 -> 0
A26: Realiza negociações de maneira bem estruturada, explorando diversas alternativas e mantendo o controle das emoções, contribuindo para alcançar soluções justas e satisfatórias para as partes envolvidas | C26: =COUNTA(B26) -> 0 | D26: =Referências!$B$4 -> 3 | E26: =C26*D26 -> 0
A27: Conduz negociações de forma altamente estruturada, antecipando alternativas e mantendo o controle emocional em todas as situações. Seu foco é garantir soluções justas, satisfatórias e equilibradas para todas as partes, promovendo um ambiente de confiança e respeito | C27: =COUNTA(B27) -> 0 | D27: =Referências!$B$5 -> 5 | E27: =C27*D27 -> 0
E28: =SUM(E24:E27) -> 0
A29: =Corporativo!F6 -> Planejamento | B29: Avaliação
A30: Capacidade de definir, organizar e executar ações, garantindo a alocação adequada de tempos e recursos para cumprimento de prazos
A31: Comportamentos observáveis | C31: =VLOOKUP(A29,Corporativo!$F$3:$G$12,2,FALSE) -> 0.25 | D31: =COUNTA(A32:A35) -> 4 | E31: =C31*E36 -> 0
A32: Apresenta dificuldades para definir, organizar e executar ações, resultando em uso inadequado de tempo e recursos, resultando em frequentes atrasos no cumprimento de prazos | C32: =COUNTA(B32) -> 0 | D32: =Referências!$B$2 -> 1 | E32: =C32*D32 -> 0
A33: Consegue planejar ações, mas enfrenta desafios na organização e execução, impactando a alocação adequada de tempo e recursos, comprometendo o cumprimento de prazos | C33: =COUNTA(B33) -> 0 | D33: =Referências!$B$3 -> 2 | E33: =C33*D33 -> 0
A34: Planeja, organiza e executa ações de forma estruturada, assegurando o uso adequado de tempo e recursos, assegurando o cumprimento dos prazos estabelecidos | C34: =COUNTA(B34) -> 0 | D34: =Referências!$B$4 -> 3 | E34: =C34*D34 -> 0
A35: Demonstra excelência na definição, organização e execução de ações, alocando adequadamente tempor e recursos, garantindo o cumprimento dos prazos | C35: =COUNTA(B35) -> 0 | D35: =Referências!$B$5 -> 5 | E35: =C35*D35 -> 0
E36: =SUM(E32:E35) -> 0
A37: =Corporativo!F7 -> Trabalho em equipe | B37: Avaliação
A38: Capacidade de atuar de forma integrada, colaborando com os demais membros da equipe e cultivando relações respeitosas que promovam um ambiente harmonioso e impulsionem o alcance dos objetivos comuns
A39: Comportamentos observáveis | C39: =VLOOKUP(A37,Corporativo!$F$3:$G$12,2,FALSE) -> 0.15 | D39: =COUNTA(A40:A43) -> 4 | E39: =C39*E44 -> 0
A40: Participa das atividades em equipe quando solicitado, sem demonstrar proatividade, e apresenta dificuldades em manter interações respeitosas e harmoniosas | C40: =COUNTA(B40) -> 0 | D40: =Referências!$B$2 -> 1 | E40: =C40*D40 -> 0
A41: Demonstra maior engajamento na colaboração com a equipe, buscando alinhar esforços e ouvir diferentes opiniões com respeito, mas ainda sem consistência, necessitando de constante orientação por parte da supervisão | C41: =COUNTA(B41) -> 0 | D41: =Referências!$B$3 -> 2 | E41: =C41*D41 -> 0
...

Sheet Analista
A2: Grupo funcional: Analista | D2: Peso total | E2: Pontuação
D3: =SUM(C7,C15,C23,C31,C39,C47) -> 1 | E3: =SUM(E7,E15,E23,E31,E39,E47) -> 0
D4: Resultado
A5: =Corporativo!H3 -> Comprometimento | B5: Avaliação | D5: =IF(E3<=[1]Referências!$B$9,[1]Referências!C9,IF(E3<=[1]Referências!$B$10,[1]Referências!$C$10,IF(E3<=[1]Referências!$B$11,[1]Referências!$C$11,IF(E3<=[1]Referências!$B$12,[1]Referências!$C$12,[1]Referências!$C$13)))) -> Não atende
A6: Capacidade de cumprir as tarefas conforme normas e prazos estabelecidos, demonstrando constância, pontualidade, assiduidade e responsabilidade
A7: Comportamentos observáveis | C7: =VLOOKUP(A5,Corporativo!$H$3:$I$12,2,FALSE) -> 0.1 | E7: =C7*E12 -> 0
A8: Cumpre as tarefas quando solicitado, mas com frequência precisa de lembretes ou orientações para seguir normas, além disso apresenta dificuldades em manter a assiduidade e a pontualidade, tanto nas entregas quanto no cumprimento de horários | C8: =COUNTA(B8) -> 0 | D8: =Referências!$B$2 -> 1 | E8: =C8*D8 -> 0
A9: Cumpre as tarefas de forma regular, apresentando pontualidade e assiduidade e seguindo as normas estabelecidas na maior parte das vezes, mas ainda requer acompanhamento | C9: =COUNTA(B9) -> 0 | D9: =Referências!$B$3 -> 2 | E9: =C9*D9 -> 0
A10: Cumpre as tarefas de maneira constante e comprometida, com aderência às normas e padrões, demonstrando responsabilidade, assiduidade e pontualidade tanto nas entregas quanto no cumprimento de horários | C10: =COUNTA(B10) -> 0 | D10: =Referências!$B$4 -> 3 | E10: =C10*D10 -> 0
A11: Realiza as tarefas de forma exemplar, atuando como modelo de compromisso e responsabilidade, influenciando positivamente os outros ao demonstrar constância, pontualidade e responsabilidade em todas as entregas | C11: =COUNTA(B11) -> 0 | D11: =Referências!$B$5 -> 5 | E11: =C11*D11 -> 0
E12: =SUM(E8:E11) -> 0
A13: =Corporativo!H4 -> Atenção | B13: Avaliação
A14: Capacidade de concentrar-se nas atividades com foco, disciplina e responsabilidade, garantindo a acurácia na execução das tarefas por meio de ações como conferência, validação de informações e prevenção de erros
A15: Comportamentos observáveis | C15: =VLOOKUP(A13,Corporativo!$H$3:$I$12,2,FALSE) -> 0.2 | D15: =COUNTA(A17:A19) -> 3 | E15: =C15*E20 -> 0
A16: Demonstra dificuldade em manter a concentração nas tarefas, cometendo erros por falta de conferência ou validação das informações, com entregas que frequentemente precisam de revisão e apoio | C16: =COUNTA(B16) -> 0 | D16: =Referências!$B$2 -> 1 | E16: =C16*D16 -> 0
A17: Realiza as atividades com atenção moderada, mas pode perder o foco em situações rotineiras ou de alta demanda, deixando passar detalhes importantes por falta de revisão cuidadosa ou validação completa dos dados | C17: =COUNTA(B17) -> 0 | D17: =Referências!$B$3 -> 2 | E17: =C17*D17 -> 0
A18: Mantém a concentração ao longo das atividades, executando-as com foco, garantindo a acurácia por meio da conferência e validação sistemática das informações, com poucos ou nenhum erro nas entregas | C18: =COUNTA(B18) -> 0 | D18: =Referências!$B$4 -> 3 | E18: =C18*D18 -> 0
A19: Atua de forma altamente focada e comprometida com a excelência das entregas, antecipando falhas, validando informações com profundidade e agindo com rigor técnico, sendo referência em atenção aos detalhes e confiabilidade nos processos | C19: =COUNTA(B19) -> 0 | D19: =Referências!$B$5 -> 5 | E19: =C19*D19 -> 0
E20: =SUM(E16:E19) -> 0
A21: =Corporativo!H5 -> Capacidade de análise | B21: Avaliação
A22: Capacidade de avaliar informações, situações ou resultados de maneira interpretativa e baseada em dados e argumentos sólidos, extraindo pontos relevantes, convergindo, construindo diagnósticos e apresentando alternativas e soluções eficazes
A23: Comportamentos observáveis | C23: =VLOOKUP(A21,Corporativo!$H$3:$I$12,2,FALSE) -> 0.2 | D23: =COUNTA(A24:A27) -> 4 | E23: =C23*E28 -> 0
A24: Avalia informações e situações de forma superficial, sem considerar dados e argumentos sólidos, frequentemente precisando de orientação para identificar pontos relevantes e extrair diagnósticos | C24: =COUNTA(B24) -> 0 | D24: =Referências!$B$2 -> 1 | E24: =C24*D24 -> 0
A25: Realiza avaliações mais fundamentadas, considerando dados e informações, mas ainda com dificuldade em convergir e sintetizar os pontos mais relevantes de maneira clara e concisa | C25: =COUNTA(B25) -> 0 | D25: =Referências!$B$3 -> 2 | E25: =C25*D25 -> 0
A26: Analisa informações e resultados de maneira interpretativa e organizada, utilizando dados e argumentos consistentes para elaborar diagnósticos claros e objetivos, extraindo os pontos mais relevantes de forma eficiente e apresentando alternativas e soluções eficazes | C26: =COUNTA(B26) -> 0 | D26: =Referências!$B$4 -> 3 | E26: =C26*D26 -> 0
A27: Realiza avaliações complexas e altamente interpretativas, extraindo ideias e construindo diagnósticos precisos, com base em dados robustos e argumentos bem fundamentados, apresentando alternativas e soluções eficazes | C27: =COUNTA(B27) -> 0 | D27: =Referências!$B$5 -> 5 | E27: =C27*D27 -> 0
E28: =SUM(E24:E27) -> 0
A29: =Corporativo!H6 -> Planejamento | B29: Avaliação
A30: Capacidade de definir, organizar e executar ações, garantindo a alocação adequada de tempos e recursos para cumprimento de prazos
A31: Comportamentos observáveis | C31: =VLOOKUP(A29,Corporativo!$H$3:$I$12,2,FALSE) -> 0.2 | D31: =COUNTA(A32:A35) -> 4 | E31: =C31*E36 -> 0
A32: Apresenta dificuldades para definir, organizar e executar ações, resultando em uso inadequado de tempo e recursos, resultando em frequentes atrasos no cumprimento de prazos | C32: =COUNTA(B32) -> 0 | D32: =Referências!$B$2 -> 1 | E32: =C32*D32 -> 0
A33: Consegue planejar ações, mas enfrenta desafios na organização e execução, impactando a alocação adequada de tempo e recursos, comprometendo o cumprimento de prazos | C33: =COUNTA(B33) -> 0 | D33: =Referências!$B$3 -> 2 | E33: =C33*D33 -> 0
A34: Planeja, organiza e executa ações de forma estruturada, assegurando o uso adequado de tempo e recursos, assegurando o cumprimento dos prazos estabelecidos | C34: =COUNTA(B34) -> 0 | D34: =Referências!$B$4 -> 3 | E34: =C34*D34 -> 0
A35: Demonstra excelência na definição, organização e execução de ações, alocando adequadamente tempo e recursos, garantindo o cumprimento dos prazos | C35: =COUNTA(B35) -> 0 | D35: =Referências!$B$5 -> 5 | E35: =C35*D35 -> 0
E36: =SUM(E32:E35) -> 0
A37: =Corporativo!H7 -> Qualidade | B37: Avaliação
A38: Operacionaliza as demandas de trabalho sem perda na qualidade dos resultados apresentados, sem incidência de erros, executando as tarefas com precisão, clareza e objetividade.
A39: Comportamentos observáveis | C39: =VLOOKUP(A37,Corporativo!$H$3:$I$12,2,FALSE) -> 0.15 | D39: =COUNTA(A40:A43) -> 4 | E39: =C39*E44 -> 0
A40: Realiza as tarefas de forma inconsistente, apresenta erros recorrentes, dificuldades para seguir processos e manter a organização, demonstrando insegurança e necessidade constante de orientação para garantir a qualidade mínima nas entregas | C40: =COUNTA(B40) -> 0 | D40: =Referências!$B$2 -> 1 | E40: =C40*D40 -> 0
A41: Executa as atividades com qualidade razoável e demonstra evolução, mas ainda com necessidade de revisões pontuais e apoio em processos menos familiares, apresentando instabilidade na manutenção da clareza, precisão e cumprimento de prazos sob pressão | C41: =COUNTA(B41) -> 0 | D41: =Referências!$B$3 -> 2 | E41: =C41*D41 -> 0
...

Sheet Encarregado e Supervisor
A2: Grupo funcional: Encarregado e Supervisor | D2: Peso total | E2: Pontuação
D3: =SUM(C7,C15,C23,C31,C39,C47) -> 1 | E3: =SUM(E7,E15,E23,E31,E39,E47) -> 0
D4: Resultado
A5: =Corporativo!J3 -> Comprometimento | B5: Avaliação | D5: =IF(E3<=[1]Referências!$B$9,[1]Referências!C9,IF(E3<=[1]Referências!$B$10,[1]Referências!$C$10,IF(E3<=[1]Referências!$B$11,[1]Referências!$C$11,IF(E3<=[1]Referências!$B$12,[1]Referências!$C$12,[1]Referências!$C$13)))) -> Não atende
A6: Capacidade de basear suas ações de trabalho no respeito às pessoas, na conduta ética e no alinhamento aos valores e princípios da empresa, demonstrando responsabilidade com os resultados, cumprimento dos prazos e acordos, contribuindo ativamente para os objetivos organizacionais
A7: Comportamentos observáveis | C7: =VLOOKUP(A5,Corporativo!$J$3:$K$12,2,FALSE) -> 0.15 | E7: =C7*E12 -> 0
A8: Demonstra comportamentos inconsistentes em relação ao respeito, à ética e aos valores da empresa, com baixo senso de responsabilidade nas entregas e dificuldades em cumprir prazos, resultando em pouca contribuição para os objetivos da equipe ou organização | C8: =COUNTA(B8) -> 0 | D8: =Referências!$B$2 -> 1 | E8: =C8*D8 -> 0
A9: Apresenta conduta ética e respeitosa na maior parte do tempo, mas com oscilação no cumprimento de prazos e acordos. Demonstra esforço para alinhar-se aos valores da empresa, mas ainda necessita de constância no comprometimento com os resultados coletivos | C9: =COUNTA(B9) -> 0 | D9: =Referências!$B$3 -> 2 | E9: =C9*D9 -> 0
A10: Baseia suas ações em comportamentos éticos, respeitosos e alinhados aos valores da organização, cumpre prazos e acordos com responsabilidade e contribui ativamente para os objetivos da equipe e da empresa, sendo reconhecido como alguém confiável e comprometido | C10: =COUNTA(B10) -> 0 | D10: =Referências!$B$4 -> 3 | E10: =C10*D10 -> 0
A11: Atua como exemplo de conduta ética e respeito, agindo de forma coerente com os valores e princípios da empresa, demonstrando alto grau de responsabilidade com os resultados, cumprindo e antecipando prazos e compromissos | C11: =COUNTA(B11) -> 0 | D11: =Referências!$B$5 -> 5 | E11: =C11*D11 -> 0
E12: =SUM(E8:E11) -> 0
A13: =Corporativo!J4 -> Eficiência | B13: Avaliação
A14: Capacidade de alcançar os resultados desejados com o mínimo de recursos possíveis, como tempo, esforço, custo e materiais, realizando as tarefas de maneira otimizada e sem desperdícios.
A15: Comportamentos observáveis | C15: =VLOOKUP(A13,Corporativo!$J$3:$K$12,2,FALSE) -> 0.15 | D15: =COUNTA(A17:A19) -> 3 | E15: =C15*E20 -> 0
A16: Realiza as tarefas sem considerar a eficiência no uso de recursos, alcançando os resultados, mas com um consumo excessivo de tempo, esforço ou custo | C16: =COUNTA(B16) -> 0 | D16: =Referências!$B$2 -> 1 | E16: =C16*D16 -> 0
A17: Realiza as tarefas preocupando-se em reduzir o uso de recursos, mas ainda com alguma margem de desperdício, necessitando de apoio para aplicar ajustes que promovam resultados eficientes | C17: =COUNTA(B17) -> 0 | D17: =Referências!$B$3 -> 2 | E17: =C17*D17 -> 0
A18: Realiza as tarefas de forma a alcançar os resultados, realizando entregas com baixo desperdício, dentro dos custos e prazos estabelecidos | C18: =COUNTA(B18) -> 0 | D18: =Referências!$B$4 -> 3 | E18: =C18*D18 -> 0
A19: Realiza as tarefas alcançando resultados com o mínimo de recursos e sem desperdícios, além de apoiar e influenciar a implementação de práticas que promovem a eficiência além do processo em que atua | C19: =COUNTA(B19) -> 0 | D19: =Referências!$B$5 -> 5 | E19: =C19*D19 -> 0
E20: =SUM(E16:E19) -> 0
A21: =Corporativo!J5 -> Gestão de Pessoas | B21: Avaliação
A22: Capacidade de influenciar, inspirar e orientar pessoas e equipes para atingir objetivos organizacionais, estabelecendo relacionamentos de confiança, promovendo o crescimento individual e coletivo
A23: Comportamentos observáveis | C23: =VLOOKUP(A21,Corporativo!$J$3:$K$12,2,FALSE) -> 0.2 | D23: =COUNTA(A24:A27) -> 4 | E23: =C23*E28 -> 0
A24: Demonstra dificuldades em influenciar e orientar os outros, estabelecendo relacionamentos superficiais ou com pouca confiança mútua devido a dificuldade de se comunicar e administrar conflitos, e requer apoio contínuo nas estratégias de desenvolvimento individual e coletivo | C24: =COUNTA(B24) -> 0 | D24: =Referências!$B$2 -> 1 | E24: =C24*D24 -> 0
A25: Consegue influenciar e orientar as pessoas de maneira moderada, estabelecendo alguns relacionamentos de confiança, mas ainda apresenta dificuldades na comunicação, enfrentando desafios para impulsionar o desenvolvimento individual e coletivo de forma consistente | C25: =COUNTA(B25) -> 0 | D25: =Referências!$B$3 -> 2 | E25: =C25*D25 -> 0
A26: Influencia, inspira e comunica-se com os outros de maneira consistente, estabelecendo relacionamentos de confiança sólidos e orientando pessoas e equipes para atingir objetivos organizacionais e promover o crescimento contínuo | C26: =COUNTA(B26) -> 0 | D26: =Referências!$B$4 -> 3 | E26: =C26*D26 -> 0
A27: Exerce uma influência significativa e inspiradora, guiando pessoas e equipes para alcançar resultados excepcionais, estabelecendo relacionamentos profundos de confiança e promovendo um crescimento contínuo e sustentável para a organização e seus membros | C27: =COUNTA(B27) -> 0 | D27: =Referências!$B$5 -> 5 | E27: =C27*D27 -> 0
E28: =SUM(E24:E27) -> 0
A29: =Corporativo!J6 -> Orientação para resultados | B29: Avaliação
A30: Capacidade de concentrar esforços, recursos e energia nas ações que geram os melhores resultados para a organização, seguindo padrões éticos e valores da empresa, buscando o alcance de resultados e cumprimento de metas
A31: Comportamentos observáveis | C31: =VLOOKUP(A29,Corporativo!$J$3:$K$12,2,FALSE) -> 0.2 | D31: =COUNTA(A32:A35) -> 4 | E31: =C31*E36 -> 0
A32: Realiza ações direcionadas ao cumprimento de tarefas, mas nem sempre identifica as prioridades ou os impactos nos resultados, necessitando de orientação para alinhar seus esforços aos objetivos organizacionais | C32: =COUNTA(B32) -> 0 | D32: =Referências!$B$2 -> 1 | E32: =C32*D32 -> 0
A33: Direciona seus esforços para atividades que impactam diretamente os objetivos organizacionais, busca resultados consistentes e demonstra clara compreensão das prioridades, atuando sempre em alinhamento com os valores e princípios da empresa | C33: =COUNTA(B33) -> 0 | D33: =Referências!$B$3 -> 2 | E33: =C33*D33 -> 0
A34: Planeja e executa ações que potencializam os resultados organizacionais, administrando recursos de maneira eficiente e ética para o alcançar metas de forma consistente, mesmo em situações desafiadoras | C34: =COUNTA(B34) -> 0 | D34: =Referências!$B$4 -> 3 | E34: =C34*D34 -> 0
A35: Concentra esforços em ações de alto impacto, otimizando recursos e inspirando outros a seguirem os valores éticos e organizacionais, atuando de forma exemplar no alcance de resultados e na superação de metas | C35: =COUNTA(B35) -> 0 | D35: =Referências!$B$5 -> 5 | E35: =C35*D35 -> 0
E36: =SUM(E32:E35) -> 0
A37: =Corporativo!J7 -> Tomada de decisão | B37: Avaliação
A38: Capacidade de avaliar informações, analisar impactos e escolher a melhor solução para desafios do dia a dia dentro do seu setor, considerando regras e objetivos organizacionais para garantir escolhas alinhadas às melhores práticas e resultados esperados
A39: Comportamentos observáveis | C39: =VLOOKUP(A37,Corporativo!$J$3:$K$12,2,FALSE) -> 0.2 | D39: =COUNTA(A40:A43) -> 4 | E39: =C39*E44 -> 0
A40: Evita tomar decisões por conta própria, aguardando orientações mesmo para questões simples, e apresenta dificuldade em avaliar impactos antes de agir | C40: =COUNTA(B40) -> 0 | D40: =Referências!$B$2 -> 1 | E40: =C40*D40 -> 0
A41: Toma decisões em situações rotineiras e previsíveis, seguindo procedimentos estabelecidos, mas ainda depende de orientação em situações mais complexas ou inesperadas | C41: =COUNTA(B41) -> 0 | D41: =Referências!$B$3 -> 2 | E41: =C41*D41 -> 0
...

Sheet Gerente
A2: Grupo funcional: Gerente | D2: Peso total | E2: Pontuação
D3: =SUM(C7,C15,C23,C31,C39) -> 1 | E3: =SUM(E7,E15,E23,E31,E39) -> 0
D4: Resultado
A5: =Corporativo!L3 -> Comprometimento | B5: Avaliação | D5: =IF(E3<=[1]Referências!$B$9,[1]Referências!C9,IF(E3<=[1]Referências!$B$10,[1]Referências!$C$10,IF(E3<=[1]Referências!$B$11,[1]Referências!$C$11,IF(E3<=[1]Referências!$B$12,[1]Referências!$C$12,[1]Referências!$C$13)))) -> Não atende
A6: Capacidade de basear suas ações de trabalho no respeito às pessoas, na conduta ética e no alinhamento aos valores e princípios da empresa, demonstrando responsabilidade com os resultados, cumprimento dos prazos e acordos, contribuindo ativamente para os objetivos organizacionais
A7: Comportamentos observáveis | C7: =VLOOKUP(A5,Corporativo!$L$3:$M$12,2,FALSE) -> 0.15 | E7: =C7*E12 -> 0
A8: Demonstra comportamentos inconsistentes em relação ao respeito, à ética e aos valores da empresa, com baixo senso de responsabilidade nas entregas e dificuldades em cumprir prazos, resultando em pouca contribuição para os objetivos da equipe ou organização | C8: =COUNTA(B8) -> 0 | D8: =Referências!$B$2 -> 1 | E8: =C8*D8 -> 0
A9: Apresenta conduta ética e respeitosa na maior parte do tempo, mas com oscilação no cumprimento de prazos e acordos. Demonstra esforço para alinhar-se aos valores da empresa, mas ainda necessita de constância no comprometimento com os resultados coletivos | C9: =COUNTA(B9) -> 0 | D9: =Referências!$B$3 -> 2 | E9: =C9*D9 -> 0
A10: Baseia suas ações em comportamentos éticos, respeitosos e alinhados aos valores da organização, cumpre prazos e acordos com responsabilidade e contribui ativamente para os objetivos da equipe e da empresa, sendo reconhecido como alguém confiável e comprometido | C10: =COUNTA(B10) -> 0 | D10: =Referências!$B$4 -> 3 | E10: =C10*D10 -> 0
A11: Atua como exemplo de conduta ética e respeito, agindo de forma coerente com os valores e princípios da empresa, demonstrando alto grau de responsabilidade com os resultados, cumprindo e antecipando prazos e compromissos | C11: =COUNTA(B11) -> 0 | D11: =Referências!$B$5 -> 5 | E11: =C11*D11 -> 0
E12: =SUM(E8:E11) -> 0
A13: =Corporativo!L4 -> Gestão de Pessoas | B13: Avaliação
A14: Capacidade de influenciar, inspirar e orientar pessoas e equipes para atingir objetivos organizacionais, estabelecendo relacionamentos de confiança, promovendo o crescimento individual e coletivo
A15: Comportamentos observáveis | C15: =VLOOKUP(A13,Corporativo!$L$3:$M$12,2,FALSE) -> 0.25 | D15: =COUNTA(A17:A19) -> 3 | E15: =C15*E20 -> 0
A16: Demonstra dificuldades em influenciar e orientar os outros, estabelecendo relacionamentos superficiais ou com pouca confiança mútua devido a dificuldade de se comunicar e administrar conflitos, e requer apoio contínuo nas estratégias de desenvolvimento individual e coletivo | C16: =COUNTA(B16) -> 0 | D16: =Referências!$B$2 -> 1 | E16: =C16*D16 -> 0
A17: Consegue influenciar e orientar as pessoas de maneira moderada, estabelecendo alguns relacionamentos de confiança, mas ainda apresenta dificuldades na comunicação, enfrentando desafios para impulsionar o desenvolvimento individual e coletivo de forma consistente | C17: =COUNTA(B17) -> 0 | D17: =Referências!$B$3 -> 2 | E17: =C17*D17 -> 0
A18: Influencia, inspira e comunica-se com os outros de maneira consistente, estabelecendo relacionamentos de confiança sólidos e orientando pessoas e equipes para atingir objetivos organizacionais e promover o crescimento contínuo | C18: =COUNTA(B18) -> 0 | D18: =Referências!$B$4 -> 3 | E18: =C18*D18 -> 0
A19: Exerce uma influência significativa e inspiradora, guiando pessoas e equipes para alcançar resultados excepcionais, estabelecendo relacionamentos profundos de confiança e promovendo um crescimento contínuo e sustentável para a organização e seus membros | C19: =COUNTA(B19) -> 0 | D19: =Referências!$B$5 -> 5 | E19: =C19*D19 -> 0
E20: =SUM(E16:E19) -> 0
A21: =Corporativo!L5 -> Orientação para resultados | B21: Avaliação
A22: Capacidade de concentrar esforços, recursos e energia nas ações que geram os melhores resultados para a organização, seguindo padrões éticos e valores da empresa, buscando o alcance de resultados e cumprimento de metas
A23: Comportamentos observáveis | C23: =VLOOKUP(A21,Corporativo!$L$3:$M$12,2,FALSE) -> 0.25 | D23: =COUNTA(A24:A27) -> 4 | E23: =C23*E28 -> 0
A24: Realiza ações direcionadas ao cumprimento de tarefas, mas nem sempre identifica as prioridades ou os impactos nos resultados, necessitando de orientação para alinhar seus esforços aos objetivos organizacionais | C24: =COUNTA(B24) -> 0 | D24: =Referências!$B$2 -> 1 | E24: =C24*D24 -> 0
A25: Direciona seus esforços para atividades que impactam diretamente os objetivos organizacionais, busca resultados consistentes e demonstra clara compreensão das prioridades, atuando sempre em alinhamento com os valores e princípios da empresa | C25: =COUNTA(B25) -> 0 | D25: =Referências!$B$3 -> 2 | E25: =C25*D25 -> 0
A26: Planeja e executa ações que potencializam os resultados organizacionais, administrando recursos de maneira eficiente e ética para o alcançar metas de forma consistente, mesmo em situações desafiadoras | C26: =COUNTA(B26) -> 0 | D26: =Referências!$B$4 -> 3 | E26: =C26*D26 -> 0
A27: Concentra esforços em ações de alto impacto, otimizando recursos e inspirando outros a seguirem os valores éticos e organizacionais, atuando de forma exemplar no alcance de resultados e na superação de metas | C27: =COUNTA(B27) -> 0 | D27: =Referências!$B$5 -> 5 | E27: =C27*D27 -> 0
E28: =SUM(E24:E27) -> 0
A29: =Corporativo!L6 -> Tomada de decisão | B29: Avaliação
A30: Desenvolve estratégias e seleciona a alternativa mais assertiva por meio de negociações estruturadas e análise de dados a fim de implementar soluções práticas que promovam o alcance de resultados e melhorias para a sustentabilidade do negócio
A31: Comportamentos observáveis | C31: =VLOOKUP(A29,Corporativo!$L$3:$M$12,2,FALSE) -> 0.25 | D31: =COUNTA(A32:A35) -> 4 | E31: =C31*E36 -> 0
A32: Enfrenta dificuldades em conduzir negociações de forma estruturada, geralmente reagindo às situações sem explorar alternativas, abordando apenas os sintomas superficiais, tendo dificuldades em tomar decisões e selecionar alternativas eficazes | C32: =COUNTA(B32) -> 0 | D32: =Referências!$B$2 -> 1 | E32: =C32*D32 -> 0
A33: Conduz negociações de forma razoavelmente estruturada, considerando algumas alternativas e identificando oportunidades, mas se sente inseguro para propor e selecionar alternativas eficazes e que impulsionem a sustentabilidade do negócio | C33: =COUNTA(B33) -> 0 | D33: =Referências!$B$3 -> 2 | E33: =C33*D33 -> 0
A34: Realiza negociações de maneira bem estruturada, explorando diversas alternativas, desenvolvendo estratégias eficazes e implementando soluções práticas que geram resultados positivos e promovem melhorias para a sustentabilidade do negócio, selecionando a melhor alternativa com base em uma análise cuidadosa de dados e informações | C34: =COUNTA(B34) -> 0 | D34: =Referências!$B$4 -> 3 | E34: =C34*D34 -> 0
A35: Conduz negociações de forma altamente estruturada, antecipando alternativas e desenvolvendo estratégias inovadoras e assertivas, implementando soluções eficazes que geram resultados excepcionais e impulsionam melhorias sustentáveis no curto e médio prazo | C35: =COUNTA(B35) -> 0 | D35: =Referências!$B$5 -> 5 | E35: =C35*D35 -> 0
E36: =SUM(E32:E35) -> 0
A37: =Corporativo!L7 -> Visão estratégica | B37: Avaliação
A38: Capacidade de compreender o cenário global em que a empresa está inserida, identificar oportunidades e ameaças, antecipar tendências e direcionar ações de longo prazo para alcançar os objetivos organizacionais e contribuir para o melhor direcionamento do negócio
A39: Comportamentos observáveis | C39: =VLOOKUP(A37,Corporativo!$L$3:$M$12,2,FALSE) -> 0.1 | D39: =COUNTA(A40:A43) -> 4 | E39: =C39*E44 -> 0
A40: Possui foco apenas no presente e nas tarefas imediatas, sem considerar tendências ou o impacto de suas ações no médio e longo prazo, demonstrando dificuldade em compreender como mudanças externas podem afetar a organização | C40: =COUNTA(B40) -> 0 | D40: =Referências!$B$2 -> 1 | E40: =C40*D40 -> 0
A41: Identifica ocasionalmente tendências e desafios que podem impactar a organização, necessitando de orientação para integrar percepções à estratégica do negócio, pois o foco no curto prazo ainda é predominante | C41: =COUNTA(B41) -> 0 | D41: =Referências!$B$3 -> 2 | E41: =C41*D41 -> 0
...

Sheet Diretor
A2: Grupo funcional: Diretor | D2: Peso total | E2: Pontuação
D3: =SUM(C7,C15,C23,C31,C39,C48) -> 1 | E3: =SUM(E7,E15,E23,E31,E39,E48) -> 0
D4: Resultado
A5: =Corporativo!N3 -> Comprometimento | B5: Avaliação | D5: =IF(E3<=[1]Referências!$B$9,[1]Referências!C9,IF(E3<=[1]Referências!$B$10,[1]Referências!$C$10,IF(E3<=[1]Referências!$B$11,[1]Referências!$C$11,IF(E3<=[1]Referências!$B$12,[1]Referências!$C$12,[1]Referências!$C$13)))) -> Não atende
A6: Capacidade de basear suas ações de trabalho no respeito às pessoas, na conduta ética e no alinhamento aos valores e princípios da empresa, demonstrando responsabilidade com os resultados, cumprimento dos prazos e acordos, contribuindo ativamente para os objetivos organizacionais
A7: Comportamentos observáveis | C7: =VLOOKUP(A5,Corporativo!$N$3:$O$12,2,FALSE) -> 0.1 | E7: =C7*E12 -> 0
A8: Demonstra comportamentos inconsistentes em relação ao respeito, à ética e aos valores da empresa, com baixo senso de responsabilidade nas entregas e dificuldades em cumprir prazos, resultando em pouca contribuição para os objetivos da equipe ou organização | C8: =COUNTA(B8) -> 0 | D8: =Referências!$B$2 -> 1 | E8: =C8*D8 -> 0
A9: Apresenta conduta ética e respeitosa na maior parte do tempo, mas com oscilação no cumprimento de prazos e acordos. Demonstra esforço para alinhar-se aos valores da empresa, mas ainda necessita de constância no comprometimento com os resultados coletivos | C9: =COUNTA(B9) -> 0 | D9: =Referências!$B$3 -> 2 | E9: =C9*D9 -> 0
A10: Baseia suas ações em comportamentos éticos, respeitosos e alinhados aos valores da organização, cumpre prazos e acordos com responsabilidade e contribui ativamente para os objetivos da equipe e da empresa, sendo reconhecido como alguém confiável e comprometido | C10: =COUNTA(B10) -> 0 | D10: =Referências!$B$4 -> 3 | E10: =C10*D10 -> 0
A11: Atua como exemplo de conduta ética e respeito, agindo de forma coerente com os valores e princípios da empresa, demonstrando alto grau de responsabilidade com os resultados, cumprindo e antecipando prazos e compromissos | C11: =COUNTA(B11) -> 0 | D11: =Referências!$B$5 -> 5 | E11: =C11*D11 -> 0
E12: =SUM(E8:E11) -> 0
A13: =Corporativo!N4 -> Gestão de Pessoas | B13: Avaliação
A14: Capacidade de influenciar, inspirar e orientar pessoas e equipes para atingir objetivos organizacionais, delegando e desdobrando os objetivos organizacionais, promovendo o crescimento individual e coletivo
A15: Comportamentos observáveis | C15: =VLOOKUP(A13,Corporativo!$N$3:$O$12,2,FALSE) -> 0.2 | D15: =COUNTA(A17:A19) -> 3 | E15: =C15*E20 -> 0
A16: Demonstra dificuldades em influenciar e orientar os outros, estabelecendo relacionamentos superficiais ou com pouca confiança mútua devido a dificuldade de se comunicar e administrar conflitos, e requer apoio contínuo nas estratégias de desenvolvimento individual e coletivo | C16: =COUNTA(B16) -> 0 | D16: =Referências!$B$2 -> 1 | E16: =C16*D16 -> 0
A17: Consegue influenciar e orientar as pessoas de maneira moderada, mas ainda apresenta dificuldades na comunicação, enfrentando desafios para desdobrar os objetivos organizacionais e impulsionar o desenvolvimento individual e coletivo de forma consistente | C17: =COUNTA(B17) -> 0 | D17: =Referências!$B$3 -> 2 | E17: =C17*D17 -> 0
A18: Influencia, inspira e comunica-se com os outros de maneira consistente, orientando pessoas e equipes para atingir objetivos organizacionais e promover o crescimento contínuo | C18: =COUNTA(B18) -> 0 | D18: =Referências!$B$4 -> 3 | E18: =C18*D18 -> 0
A19: Exerce uma influência significativa e inspiradora, guiando pessoas e equipes para alcançar resultados excepcionais, desdobrando com excelência e estratégia os objetivos organizacionais e promovendo um crescimento contínuo e sustentável para a organização e seus membros | C19: =COUNTA(B19) -> 0 | D19: =Referências!$B$5 -> 5 | E19: =C19*D19 -> 0
E20: =SUM(E16:E19) -> 0
A21: =Corporativo!N5 -> Gestão de recursos | B21: Avaliação
A22: Capacidade de alocar e otimizar o uso dos recursos disponíveis (humanos, ativos, tecnológicos, materiais, financeiros) garantindo que sejam utilizados de forma eficiente e sustentável para maximizar os resultados do negócio
A23: Comportamentos observáveis | C23: =VLOOKUP(A21,Corporativo!$N$3:$O$12,2,FALSE) -> 0.25 | D23: =COUNTA(A24:A27) -> 4 | E23: =C23*E28 -> 0
A24: Não planeja e utiliza os recursos de forma desorganizada, resultando em desperdícios, baixa produtividade, alocação inadequada de ativos e instabilidade financeira | C24: =COUNTA(B24) -> 0 | D24: =Referências!$B$2 -> 1 | E24: =C24*D24 -> 0
A25: Planeja a aloca dos recursos, porém sem visão estratégica, gerando desperdício ou uso inadequado dos recursos, podendo alcançar resultados, mas sem eficiência | C25: =COUNTA(B25) -> 0 | D25: =Referências!$B$3 -> 2 | E25: =C25*D25 -> 0
A26: Gerencia os recursos de forma estruturada e eficiente, garantindo adequada alocação dos recursos, identificando oportunidades de melhoria e ajustando estratégias conforme necessário | C26: =COUNTA(B26) -> 0 | D26: =Referências!$B$4 -> 3 | E26: =C26*D26 -> 0
A27: Atua com excelência na gestão estratégica dos recursos, maximizando a eficiência operacional, reduzindo desperdícios e garantindo investimentos sustentáveis, tornando-se referência na organização | C27: =COUNTA(B27) -> 0 | D27: =Referências!$B$5 -> 5 | E27: =C27*D27 -> 0
E28: =SUM(E24:E27) -> 0
A29: =Corporativo!N6 -> Relacionamento interpessoal | B29: Avaliação
A30: Capacidade de influenciar e se conectar com pessoas para atingir objetivos organizacionais, administrando conflitos e estabelecendo relacionamentos de confiança com colaboradores, comunidade, clientes e fornecedores (stakeholders), contribuindo diretamente para o crescimento organizacional
A31: Comportamentos observáveis | C31: =VLOOKUP(A29,Corporativo!$N$3:$O$12,2,FALSE) -> 0.1 | D31: =COUNTA(A32:A35) -> 4 | E31: =C31*E36 -> 0
A32: Interage de forma limitada, focando apenas nas próprias responsabilidades, apresentando dificuldade em administrar conflitos, estabelecer conexões de confiança e influenciar pessoas | C32: =COUNTA(B32) -> 0 | D32: =Referências!$B$2 -> 1 | E32: =C32*D32 -> 0
A33: Mantém boas relações com colaboradores, comunidade, clientes e fornecedores, comunicando-se de forma respeitosa, administrando conflitos e contribuindo para estabelecer relacionamentos de confiança, mas ainda tem pouca influência sobre os outros | C33: =COUNTA(B33) -> 0 | D33: =Referências!$B$3 -> 2 | E33: =C33*D33 -> 0
A34: Constrói relacionamentos de confiança, administrando bem os conflitos e influenciando positivamente colaboradores, comunidade, clientes e fornecedores para o alcançar objetivos e promover um ambiente colaborativo e motivador | C34: =COUNTA(B34) -> 0 | D34: =Referências!$B$4 -> 3 | E34: =C34*D34 -> 0
A35: Atua como referência no relacionamento interpessoal, inspirando e engajando pessoas para atingir metas organizacionais, promover o desenvolvimento dos outros e fortalecer a cultura de confiança e crescimento na organização | C35: =COUNTA(B35) -> 0 | D35: =Referências!$B$5 -> 5 | E35: =C35*D35 -> 0
E36: =SUM(E32:E35) -> 0
A37: =Corporativo!N7 -> Resiliência | B37: Avaliação
A38: Capacidade de se adaptar e se recuperar diante de adversidades, mudanças inesperadas ou crises, mantendo ou retomando rapidamente a eficiência e o foco nos objetivos estratégicos, aprendendo com as experiências e reconhecendo limitações, mantendo o equilíbrio emocional e a colaboração, tornando-se mais preparado para lidar com desafios futuros
A39: Comportamentos observáveis | C39: =VLOOKUP(A37,Corporativo!$N$3:$O$12,2,FALSE) -> 0.1 | D39: =COUNTA(A40:A43) -> 4 | E39: =C39*E44 -> 0
A40: Reconhece as adversidades e crises quando elas surgem, mas sua adaptação é muitas vezes lenta e marcada por reações impulsivas, apresentado dificuldades em retomar o equilíbrio emocional, a eficiência e os objetivos rapidamente | C40: =COUNTA(B40) -> 0 | D40: =Referências!$B$2 -> 1 | E40: =C40*D40 -> 0
A41: Responde de maneira mais estruturada às adversidades e mudanças inesperadas, recuperando a eficiência e foco nos objetivos estratégicos de forma mais ágil e aprendendo com as experiências vividas, embora a preparação para novos desafios ainda esteja em desenvolvimento | C41: =COUNTA(B41) -> 0 | D41: =Referências!$B$3 -> 2 | E41: =C41*D41 -> 0
...

Sheet Referências
A1: Avaliação | B1: Pontuação
A2: Não atende | B2: 1
A3: Atende parcialmente | B3: 2
A4: Atende | B4: 3
A5: Supera | B5: 5
A7: Pontuação final da avaliação
A8: Referência | C8: Resultado
A9: Igual ou menor que | B9: 1.6 | C9: Não atende
A10: Igual ou menor que | B10: 2.6 | C10: Atende parcialmente | H10: Não atende | N10: Atende parcialmente | X10: Atende | AH10: Supera | AQ10: Supera muito | CN10: Supera muito
A11: Igual ou menor que | B11: 3.6 | C11: Atende | H11: Abaixo do esperado | X11: Dentro do esperado | AH11: Acima do esperado
A12: Igual ou menor que | B12: 4.5 | C12: Supera
A13: Maior que | B13: =B12 -> 4.5 | C13: Supera muito

Sheet Resultado
A1: Resultado consolidado da Avaliação de Desempenho | F1: Pesos
G2: 0.1
A3: Nome do Colaborador | B3: Eixo | C3: Área | D3: Cargo | E3: Nome do avaliador | F3: Nota Gestor | G3: Nota Auto avaliação | H3: Nota final | I3: Resultado final
A4: Exemplo | F4: 2.9 | G4: 4 | H4: =(F4*$F$2)+(G4*$G$2) -> 0.4 | I4: =IF($H4<=Referências!#REF!,Referências!#REF!,IF($H4<=Referências!#REF!,Referências!#REF!,IF($H4<=Referências!#REF!,Referências!#REF!,Referências!#REF!))) -> #REF!
A5: Exemplo | F5: 3.2 | G5: 3.8 | H5: =(F5*$F$2)+(G5*$G$2) -> 0.38 | I5: =IF($H5<=Referências!#REF!,Referências!#REF!,IF($H5<=Referências!#REF!,Referências!#REF!,IF($H5<=Referências!#REF!,Referências!#REF!,Referências!#REF!))) -> #REF!
A6: Exemplo | F6: 4.2 | G6: 4.5 | H6: =(F6*$F$2)+(G6*$G$2) -> 0.45 | I6: =IF($H6<=Referências!#REF!,Referências!#REF!,IF($H6<=Referências!#REF!,Referências!#REF!,IF($H6<=Referências!#REF!,Referências!#REF!,Referências!#REF!))) -> #REF!
A7: Exemplo | F7: 1.5 | G7: 2.8 | H7: =(F7*$F$2)+(G7*$G$2) -> 0.28 | I7: =IF($H7<=Referências!#REF!,Referências!#REF!,IF($H7<=Referências!#REF!,Referências!#REF!,IF($H7<=Referências!#REF!,Referências!#REF!,Referências!#REF!))) -> #REF!
A8: Exemplo | F8: 2.8 | G8: 3.6 | H8: =(F8*$F$2)+(G8*$G$2) -> 0.36 | I8: =IF($H8<=Referências!#REF!,Referências!#REF!,IF($H8<=Referências!#REF!,Referências!#REF!,IF($H8<=Referências!#REF!,Referências!#REF!,Referências!#REF!))) -> #REF!
