Workbook
Name _DAT1: #REF!
Name _DAT1: #REF!
Name _DAT1: #REF!
Name _DAT10: #REF!
Name _DAT10: #REF!
Name _dat105: #REF!
Name _dat105: #REF!
Name _DAT11: #REF!
Name _DAT11: #REF!
Name _DAT12: #REF!
Name _DAT12: #REF!
Name _DAT13: #REF!
Name _DAT13: #REF!
Name _DAT14: #REF!
Name _DAT14: #REF!
Name _DAT15: #REF!
Name _DAT15: #REF!
Name _DAT16: #REF!
Name _DAT16: #REF!
Name _DAT17: #REF!
Name _DAT17: #REF!
Name _DAT18: #REF!
Name _DAT18: #REF!
Name _DAT19: #REF!
Name _DAT19: #REF!
Name _DAT2: #REF!
Name _DAT2: #REF!
Name _DAT20: #REF!
Name _DAT20: #REF!
Name _DAT3: #REF!
Name _DAT3: #REF!
Name _DAT4: #REF!
Name _DAT4: #REF!
Name _DAT5: #REF!
Name _DAT5: #REF!
Name _DAT6: #REF!
Name _DAT6: #REF!
Name _DAT7: #REF!
Name _DAT7: #REF!
Name _DAT8: #REF!
Name _DAT8: #REF!
Name _DAT9: #REF!
Name _DAT9: #REF!
Name ACUMULACAO: #REF!
Name ACUMULACAO: #REF!
Name Administrativo: #REF!
Name Administrativo: #REF!
Name Format2Print: #REF!
Name IDCARGO: #REF!
Name IDCARGO: #REF!
Name IDCARGO: #REF!
Name NP: #REF!
Name NP: #REF!
Name QP: #REF!
Name QP: #REF!
Name TABMOL: #REF!
Name TABMOL: #REF!
Name TEST1: #REF!
Name TEST1: #REF!
Name TEST2: #REF!

Sheet Agregados Agro
B1: Operacional | D1: Técnico Administrativo | F1: Encarregado | H1: Supervisor e Gerente | J1: Diretor
B2: Competências | C2: Peso | D2: Competências | E2: Peso | F2: Competências | G2: Peso | H2: Competências | I2: Peso | J2: Competências | K2: Peso
A3: 1 | B3: Eficiência | C3: 0.1 | D3: Eficiência | E3: 0.15 | F3: Eficiência | G3: 0.15 | H3: Eficiência | I3: 0.1 | J3: Eficiência | K3: 0.1
A4: 2 | B4: Comprometimento | C4: 0.4 | D4: Comprometimento | E4: 0.2 | F4: Comprometimento | G4: 0.2 | H4: Comprometimento | I4: 0.2 | J4: Comprometimento | K4: 0.1
A5: 3 | B5: Orientação para segurança | C5: 0.25 | D5: Capacidade de análise | E5: 0.2 | F5: Gestão de Pessoas | G5: 0.2 | H5: Gestão de Pessoas | I5: 0.2 | J5: Gestão de Pessoas | K5: 0.15
A6: 4 | B6: Proatividade | C6: 0.1 | D6: Orientação para segurança | E6: 0.1 | F6: Orientação para segurança | G6: 0.15 | H6: Orientação para segurança | I6: 0.15 | J6: Orientação para segurança | K6: 0.1
A7: 5 | B7: Trabalho em equipe | C7: 0.15 | D7: Proatividade | E7: 0.15 | F7: Proatividade | G7: 0.1 | H7: Visão sistêmica | I7: 0.15 | J7: Relacionamento interpessoal | K7: 0.2
A8: 6 | D8: Trabalho em equipe | E8: 0.2 | F8: Tomada de decisão | G8: 0.2 | H8: Tomada de decisão | I8: 0.2 | J8: Resiliência | K8: 0.2
A9: 7 | J9: Tomada de decisão | K9: 0.15
A10: 8
A11: 9
A12: 10
B13: Soma | C13: =SUM(C3:C12) -> 1 | D13: Soma | E13: =SUM(E3:E12) -> 1 | F13: Soma | G13: =SUM(G3:G12) -> 1 | H13: Soma | I13: =SUM(I3:I12) -> 1 | J13: Soma | K13: =SUM(K3:K12) -> 1

Sheet Operacional
A2: Grupo funcional: Operacional | D2: Peso total | E2: Pontuação
D3: =SUM(C7,C15,C23,C31,C39) -> 1 | E3: =SUM(E7,E15,E23,E31,E39) -> 0
D4: Resultado
A5: ='Agregados Agro'!B3 -> Eficiência | B5: Avaliação | D5: =IF(E3<=[1]Referências!$B$9,[1]Referências!C9,IF(E3<=[1]Referências!$B$10,[1]Referências!$C$10,IF(E3<=[1]Referências!$B$11,[1]Referências!$C$11,IF(E3<=[1]Referências!$B$12,[1]Referências!$C$12,[1]Referências!$C$13)))) -> Não atende
A6: Capacidade de alcançar os resultados desejados com o mínimo de recursos possíveis, como tempo, esforço, custo e materiais, realizando as tarefas de maneira otimizada e sem desperdícios.
A7: Comportamentos observáveis | C7: =VLOOKUP(A5,'Agregados Agro'!$B$3:$C$12,2,FALSE) -> 0.1 | E7: =C7*E12 -> 0
A8: Realiza as tarefas sem considerar a eficiência no uso de recursos, alcançando os resultados, mas com um consumo excessivo de tempo, esforço ou custo | C8: =COUNTA(B8) -> 0 | D8: =Referências!$B$2 -> 1 | E8: =C8*D8 -> 0
A9: Realiza as tarefas preocupando-se em reduzir o uso de recursos, mas ainda com alguma margem de desperdício, necessitando de apoio para aplicar ajustes que promovam resultados eficientes | C9: =COUNTA(B9) -> 0 | D9: =Referências!$B$3 -> 2 | E9: =C9*D9 -> 0
A10: Realiza as tarefas de forma a alcançar os resultados, realizando entregas com baixo desperdício, dentro dos custos e prazos estabelecidos | C10: =COUNTA(B10) -> 0 | D10: =Referências!$B$4 -> 3 | E10: =C10*D10 -> 0
A11: Realiza as tarefas alcançando resultados com o mínimo de recursos e sem desperdícios, além de apoiar e influenciar a implementação de práticas que promovem a eficiência além do processo em que atua | C11: =COUNTA(B11) -> 0 | D11: =Referências!$B$5 -> 5 | E11: =C11*D11 -> 0
E12: =SUM(E8:E11) -> 0
A13: ='Agregados Agro'!B4 -> Comprometimento | B13: Avaliação
A14: Capacidade de cumprir as tarefas conforme normas, procedimentos e prazos estabelecidos, demonstrando constância, pontualidade e responsabilidade
A15: Comportamentos observáveis | C15: =VLOOKUP(A13,'Agregados Agro'!$B$3:$C$12,2,FALSE) -> 0.4 | D15: =COUNTA(A17:A19) -> 3 | E15: =C15*E20 -> 0
A16: Cumpre as tarefas quando solicitado, mas com frequência precisa de lembretes ou orientações para seguir normas e procedimentos, além disso apresenta dificuldades em manter a constância e a pontualidade nas entregas | C16: =COUNTA(B16) -> 0 | D16: =Referências!$B$2 -> 1 | E16: =C16*D16 -> 0
A17: Cumpre as tarefas de forma regular, apresentando pontualidade e seguindo as normas e procedimentos estabelecidos na maior parte das vezes | C17: =COUNTA(B17) -> 0 | D17: =Referências!$B$3 -> 2 | E17: =C17*D17 -> 0
A18: Cumpre as tarefas de maneira constante e comprometida, com aderência às normas, procedimentos e padrões, demonstrando responsabilidade e pontualidade | C18: =COUNTA(B18) -> 0 | D18: =Referências!$B$4 -> 3 | E18: =C18*D18 -> 0
A19: Realiza as tarefas de forma exemplar, atuando como modelo de compromisso e responsabilidade, influenciando positivamente os outros ao demonstrar constância, pontualidade e responsabilidade em todas as entregas | C19: =COUNTA(B19) -> 0 | D19: =Referências!$B$5 -> 5 | E19: =C19*D19 -> 0
E20: =SUM(E16:E19) -> 0
A21: ='Agregados Agro'!B5 -> Orientação para segurança | B21: Avaliação
A22: Capacidade de priorizar a integridade física no ambiente de trabalho, seguindo normas, identificando riscos e adotando comportamentos preventivos para evitar acidentes, envolvendo uma postura ativa na promoção de um ambiente seguro para si e para os demais.
A23: Comportamentos observáveis | C23: =VLOOKUP(A21,'Agregados Agro'!$B$3:$C$12,2,FALSE) -> 0.25 | D23: =COUNTA(A24:A27) -> 4 | E23: =C23*E28 -> 0
A24: Segue as normas de segurança apenas quando exigido, age de forma reativa diante de riscos e não se preocupa em identificar ou relatar potenciais perigos no ambiente de trabalho | C24: =COUNTA(B24) -> 0 | D24: =Referências!$B$2 -> 1 | E24: =C24*D24 -> 0
A25: Adota práticas seguras no dia a dia, respeita normas e sinaliza riscos quando identificados, mas não age proativamente para promover a segurança de forma ampla | C25: =COUNTA(B25) -> 0 | D25: =Referências!$B$3 -> 2 | E25: =C25*D25 -> 0
A26: Além de cumprir as normas, antecipa e reporta riscos, orienta colegas sobre práticas seguras e busca melhorar processos para reduzir acidentes e incidentes | C26: =COUNTA(B26) -> 0 | D26: =Referências!$B$4 -> 3 | E26: =C26*D26 -> 0
A27: Atua como referência em segurança, inspira e orienta os outros, propõe e participa ativamente da implementação de melhorias nos procedimentos e age antecipadamente para eliminar riscos, contribuindo para um ambiente de trabalho mais seguro e preventivo | C27: =COUNTA(B27) -> 0 | D27: =Referências!$B$5 -> 5 | E27: =C27*D27 -> 0
E28: =SUM(E24:E27) -> 0
A29: ='Agregados Agro'!B6 -> Proatividade | B29: Avaliação
A30: Capacidade de agir de forma antecipada e responsável para evitar problemas, melhorar processos, atuando com iniciativa, atenção aos detalhes.
A31: Comportamentos observáveis | C31: =VLOOKUP(A29,'Agregados Agro'!$B$3:$C$12,2,FALSE) -> 0.1 | D31: =COUNTA(A32:A35) -> 4 | E31: =C31*E36 -> 0
A32: Atua apenas quando solicitado, aguarda instruções para iniciar qualquer atividade e não demonstra preocupação em antecipar problemas ou propor melhorias | C32: =COUNTA(B32) -> 0 | D32: =Referências!$B$2 -> 1 | E32: =C32*D32 -> 0
A33: Cumpre suas funções com qualidade e dentro dos prazos, sinaliza problemas à liderança, mas não busca soluções por conta própria, e participa de iniciativas de melhoria quando solicitado | C33: =COUNTA(B33) -> 0 | D33: =Referências!$B$3 -> 2 | E33: =C33*D33 -> 0
A34: Identifica problemas e propõe soluções antes que impactem o trabalho, busca melhorias para sua rotina e compartilha boas práticas, além de apoiar colegas quando percebe dificuldades | C34: =COUNTA(B34) -> 0 | D34: =Referências!$B$4 -> 3 | E34: =C34*D34 -> 0
A35: Atua como referência para a equipe, inspira colegas a serem mais proativos, antecipa falhas, propõe e participa ativamente da implementação de melhorias | C35: =COUNTA(B35) -> 0 | D35: =Referências!$B$5 -> 5 | E35: =C35*D35 -> 0
E36: =SUM(E32:E35) -> 0
A37: ='Agregados Agro'!B7 -> Trabalho em equipe | B37: Avaliação
A38: Capacidade de agir proativamente para o alcance dos objetivos coletivos, comunicando-se de forma clara, demonstrando interesse em compreender as necessidades do outro e contribuir para a criação de soluções conjuntas
A39: Comportamentos observáveis | C39: =VLOOKUP(A37,'Agregados Agro'!$B$3:$C$12,2,FALSE) -> 0.15 | D39: =COUNTA(A40:A43) -> 4 | E39: =C39*E44 -> 0
A40: Demonstra esforço limitado para agir proativamente, apresentando dificuldade em se expressar e geralmente aguarda orientações para contribuir com os objetivos coletivos | C40: =COUNTA(B40) -> 0 | D40: =Referências!$B$2 -> 1 | E40: =C40*D40 -> 0
A41: Age de forma mais proativa, comunicando-se de forma clara e buscando entender as necessidades dos outros e contribuindo para soluções coletivas, embora ainda dependa de alguma orientação para identificar as melhores formas de colaborar | C41: =COUNTA(B41) -> 0 | D41: =Referências!$B$3 -> 2 | E41: =C41*D41 -> 0
...

Sheet Técnico Administrativo
A2: Grupo funcional: Técnico Administrativo | D2: Peso total | E2: Pontuação
D3: =SUM(C7,C15,C23,C31,C39,C47) -> 1 | E3: =SUM(E7,E15,E23,E31,E39,E47) -> 0
D4: Resultado
A5: ='Agregados Agro'!D3 -> Eficiência | B5: Avaliação | D5: =IF(E3<=[1]Referências!$B$9,[1]Referências!C9,IF(E3<=[1]Referências!$B$10,[1]Referências!$C$10,IF(E3<=[1]Referências!$B$11,[1]Referências!$C$11,IF(E3<=[1]Referências!$B$12,[1]Referências!$C$12,[1]Referências!$C$13)))) -> Não atende
A6: Capacidade de alcançar os resultados desejados com o mínimo de recursos possíveis, como tempo, esforço, custo e materiais, realizando as tarefas de maneira otimizada e sem desperdícios.
A7: Comportamentos observáveis | C7: =VLOOKUP(A5,'Agregados Agro'!$D$3:$E$12,2,FALSE) -> 0.15 | E7: =C7*E12 -> 0
A8: Realiza as tarefas sem considerar a eficiência no uso de recursos, alcançando os resultados, mas com um consumo excessivo de tempo, esforço ou custo | C8: =COUNTA(B8) -> 0 | D8: =Referências!$B$2 -> 1 | E8: =C8*D8 -> 0
A9: Realiza as tarefas preocupando-se em reduzir o uso de recursos, mas ainda com alguma margem de desperdício, necessitando de apoio para aplicar ajustes que promovam resultados eficientes | C9: =COUNTA(B9) -> 0 | D9: =Referências!$B$3 -> 2 | E9: =C9*D9 -> 0
A10: Realiza as tarefas de forma a alcançar os resultados, realizando entregas com baixo desperdício, dentro dos custos e prazos estabelecidos | C10: =COUNTA(B10) -> 0 | D10: =Referências!$B$4 -> 3 | E10: =C10*D10 -> 0
A11: Realiza as tarefas alcançando resultados com o mínimo de recursos e sem desperdícios, além de apoiar e influenciar a implementação de práticas que promovem a eficiência além do processo em que atua | C11: =COUNTA(B11) -> 0 | D11: =Referências!$B$5 -> 5 | E11: =C11*D11 -> 0
E12: =SUM(E8:E11) -> 0
A13: ='Agregados Agro'!D4 -> Comprometimento | B13: Avaliação
A14: Capacidade de cumprir as tarefas conforme normas, procedimentos e prazos estabelecidos, demonstrando constância, pontualidade e responsabilidade
A15: Comportamentos observáveis | C15: =VLOOKUP(A13,'Agregados Agro'!$D$3:$E$12,2,FALSE) -> 0.2 | D15: =COUNTA(A17:A19) -> 3 | E15: =C15*E20 -> 0
A16: Cumpre as tarefas quando solicitado, mas com frequência precisa de lembretes ou orientações para seguir normas e procedimentos, além disso apresenta dificuldades em manter a constância e a pontualidade nas entregas | C16: =COUNTA(B16) -> 0 | D16: =Referências!$B$2 -> 1 | E16: =C16*D16 -> 0
A17: Cumpre as tarefas de forma regular, apresentando pontualidade e seguindo as normas e procedimentos estabelecidos na maior parte das vezes, além de esforçar-se para cumprir meta e indicadores | C17: =COUNTA(B17) -> 0 | D17: =Referências!$B$3 -> 2 | E17: =C17*D17 -> 0
A18: Cumpre as tarefas de maneira constante e comprometida, com aderência às normas, procedimentos e padrões, demonstrando responsabilidade e pontualidade no que diz respeito às metas e indicadores | C18: =COUNTA(B18) -> 0 | D18: =Referências!$B$4 -> 3 | E18: =C18*D18 -> 0
A19: Realiza as tarefas de forma exemplar, atuando como modelo de compromisso e responsabilidade, influenciando positivamente os outros ao demonstrar constância, pontualidade e responsabilidade em todas as entregas, metas e indicadores | C19: =COUNTA(B19) -> 0 | D19: =Referências!$B$5 -> 5 | E19: =C19*D19 -> 0
E20: =SUM(E16:E19) -> 0
A21: ='Agregados Agro'!D5 -> Capacidade de análise | B21: Avaliação
A22: Capacidade de avaliar informações, situações ou resultados de maneira interpretativa e baseada em dados e argumentos sólidos, extraindo pontos relevantes, convergindo e construindo diagnósticos de forma resumida
A23: Comportamentos observáveis | C23: =VLOOKUP(A21,'Agregados Agro'!$D$3:$E$12,2,FALSE) -> 0.2 | D23: =COUNTA(A24:A27) -> 4 | E23: =C23*E28 -> 0
A24: Avalia informações e situações de forma superficial, sem considerar dados e argumentos sólidos, frequentemente precisando de orientação para identificar pontos relevantes e extrair diagnósticos | C24: =COUNTA(B24) -> 0 | D24: =Referências!$B$2 -> 1 | E24: =C24*D24 -> 0
A25: Realiza avaliações mais fundamentadas, considerando dados e informações, mas ainda com alguma dificuldade em convergir e sintetizar os pontos mais relevantes de maneira clara e concisa | C25: =COUNTA(B25) -> 0 | D25: =Referências!$B$3 -> 2 | E25: =C25*D25 -> 0
A26: Analisa informações e resultados de maneira interpretativa e organizada, utilizando dados e argumentos consistentes para elaborar diagnósticos claros e objetivos, extraindo os pontos mais relevantes de forma eficiente | C26: =COUNTA(B26) -> 0 | D26: =Referências!$B$4 -> 3 | E26: =C26*D26 -> 0
A27: Realiza avaliações complexas e altamente interpretativas, extraindo ideias e construindo diagnósticos precisos, com base em dados robustos e argumentos bem fundamentados, apresentando as informações de forma resumida, mas com impacto e clareza | C27: =COUNTA(B27) -> 0 | D27: =Referências!$B$5 -> 5 | E27: =C27*D27 -> 0
E28: =SUM(E24:E27) -> 0
A29: ='Agregados Agro'!D6 -> Orientação para segurança | B29: Avaliação
A30: Capacidade de priorizar a integridade física no ambiente de trabalho, seguindo normas, identificando riscos e adotando comportamentos preventivos para evitar acidentes, envolvendo uma postura ativa na promoção de um ambiente seguro para si e para os demais.
A31: Comportamentos observáveis | C31: =VLOOKUP(A29,'Agregados Agro'!$D$3:$E$12,2,FALSE) -> 0.1 | D31: =COUNTA(A32:A35) -> 4 | E31: =C31*E36 -> 0
A32: Segue as normas de segurança apenas quando exigido, age de forma reativa diante de riscos e não se preocupa em identificar ou relatar potenciais perigos no ambiente de trabalho | C32: =COUNTA(B32) -> 0 | D32: =Referências!$B$2 -> 1 | E32: =C32*D32 -> 0
A33: Adota práticas seguras no dia a dia, respeita normas e sinaliza riscos quando identificados, mas não age proativamente para promover a segurança de forma ampla | C33: =COUNTA(B33) -> 0 | D33: =Referências!$B$3 -> 2 | E33: =C33*D33 -> 0
A34: Além de cumprir as normas, antecipa e reporta riscos, orienta colegas sobre práticas seguras e busca melhorar processos para reduzir acidentes e incidentes | C34: =COUNTA(B34) -> 0 | D34: =Referências!$B$4 -> 3 | E34: =C34*D34 -> 0
A35: Atua como referência em segurança, inspira e orienta os outros, propõe e participa ativamente da implementação de melhorias nos procedimentos e age antecipadamente para eliminar riscos, contribuindo para um ambiente de trabalho mais seguro e preventivo | C35: =COUNTA(B35) -> 0 | D35: =Referências!$B$5 -> 5 | E35: =C35*D35 -> 0
E36: =SUM(E32:E35) -> 0
A37: ='Agregados Agro'!D7 -> Proatividade | B37: Avaliação
A38: Capacidade de agir de forma antecipada e responsável para evitar problemas, melhorar processos, atuando com iniciativa, atenção aos detalhes.
A39: Comportamentos observáveis | C39: =VLOOKUP(A37,'Agregados Agro'!$D$3:$E$12,2,FALSE) -> 0.15 | D39: =COUNTA(A40:A43) -> 4 | E39: =C39*E44 -> 0
A40: Atua apenas quando solicitado, aguarda instruções para iniciar qualquer atividade e não demonstra preocupação em antecipar problemas ou propor melhorias | C40: =COUNTA(B40) -> 0 | D40: =Referências!$B$2 -> 1 | E40: =C40*D40 -> 0
A41: Cumpre suas funções com qualidade e dentro dos prazos, sinaliza problemas à liderança, mas não busca soluções por conta própria, e participa de iniciativas de melhoria quando solicitado | C41: =COUNTA(B41) -> 0 | D41: =Referências!$B$3 -> 2 | E41: =C41*D41 -> 0
...

Sheet Encarregado
A2: Grupo funcional: Encarregado | D2: Peso total | E2: Pontuação
D3: =SUM(C7,C15,C23,C31,C39,C47) -> 1 | E3: =SUM(E7,E15,E23,E31,E39,E47) -> 0
D4: Resultado
A5: ='Agregados Agro'!F3 -> Eficiência | B5: Avaliação | D5: =IF(E3<=[1]Referências!$B$9,[1]Referências!C9,IF(E3<=[1]Referências!$B$10,[1]Referências!$C$10,IF(E3<=[1]Referências!$B$11,[1]Referências!$C$11,IF(E3<=[1]Referências!$B$12,[1]Referências!$C$12,[1]Referências!$C$13)))) -> Não atende
A6: Capacidade de alcançar os resultados desejados com o mínimo de recursos possíveis, como tempo, esforço, custo e materiais, realizando as tarefas de maneira otimizada e sem desperdícios.
A7: Comportamentos observáveis | C7: =VLOOKUP(A5,'Agregados Agro'!$F$3:$G$12,2,FALSE) -> 0.15 | E7: =C7*E12 -> 0
A8: Realiza as tarefas sem considerar a eficiência no uso de recursos, alcançando os resultados, mas com um consumo excessivo de tempo, esforço ou custo | C8: =COUNTA(B8) -> 0 | D8: =Referências!$B$2 -> 1 | E8: =C8*D8 -> 0
A9: Realiza as tarefas preocupando-se em reduzir o uso de recursos, mas ainda com alguma margem de desperdício, necessitando de apoio para aplicar ajustes que promovam resultados eficientes | C9: =COUNTA(B9) -> 0 | D9: =Referências!$B$3 -> 2 | E9: =C9*D9 -> 0
A10: Realiza as tarefas de forma a alcançar os resultados, realizando entregas com baixo desperdício, dentro dos custos e prazos estabelecidos | C10: =COUNTA(B10) -> 0 | D10: =Referências!$B$4 -> 3 | E10: =C10*D10 -> 0
A11: Realiza as tarefas alcançando resultados com o mínimo de recursos e sem desperdícios, além de apoiar e influenciar a implementação de práticas que promovem a eficiência além do processo em que atua | C11: =COUNTA(B11) -> 0 | D11: =Referências!$B$5 -> 5 | E11: =C11*D11 -> 0
E12: =SUM(E8:E11) -> 0
A13: ='Agregados Agro'!F4 -> Comprometimento | B13: Avaliação
A14: Capacidade de cumprir o planejamento e metas conforme normas, procedimentos e prazos estabelecidos, demonstrando constância, pontualidade e responsabilidade no alcance dos objetivos setoriais
A15: Comportamentos observáveis | C15: =VLOOKUP(A13,'Agregados Agro'!$F$3:$G$12,2,FALSE) -> 0.2 | D15: =COUNTA(A17:A19) -> 3 | E15: =C15*E20 -> 0
A16: Cumpre o planejamento e metas, mas com frequência precisa de orientações para cumprir prazos e realizar as entregas conforme estabelecido, apresentando dificuldades em manter a constância e a pontualidade nas entregas | C16: =COUNTA(B16) -> 0 | D16: =Referências!$B$2 -> 1 | E16: =C16*D16 -> 0
A17: Cumpre o planejamento e metas de forma regular, apresentando pontualidade e seguindo as normas e procedimentos estabelecidos na maior parte das vezes | C17: =COUNTA(B17) -> 0 | D17: =Referências!$B$3 -> 2 | E17: =C17*D17 -> 0
A18: Cumpre o planejamento e as metas de maneira constante e comprometida, com aderência às normas, procedimentos e padrões, demonstrando responsabilidade e pontualidade nas entregas | C18: =COUNTA(B18) -> 0 | D18: =Referências!$B$4 -> 3 | E18: =C18*D18 -> 0
A19: Realiza as tarefas de forma exemplar, atuando como modelo de compromisso e responsabilidade, influenciando positivamente os outros ao demonstrar constância, pontualidade e responsabilidade em todas as entregas | C19: =COUNTA(B19) -> 0 | D19: =Referências!$B$5 -> 5 | E19: =C19*D19 -> 0
E20: =SUM(E16:E19) -> 0
A21: ='Agregados Agro'!F5 -> Gestão de Pessoas | B21: Avaliação
A22: Capacidade de influenciar, inspirar e orientar pessoas e equipes para atingir objetivos organizacionais, estabelecendo relacionamentos de confiança, promovendo o crescimento individual e coletivo
A23: Comportamentos observáveis | C23: =VLOOKUP(A21,'Agregados Agro'!$F$3:$G$12,2,FALSE) -> 0.2 | D23: =COUNTA(A24:A27) -> 4 | E23: =C23*E28 -> 0
A24: Demonstra dificuldades em influenciar e orientar os outros, estabelecendo relacionamentos superficiais ou com pouca confiança mútua devido a dificuldade de se comunicar e administrar conflitos, e requer apoio contínuo nas estratégias de desenvolvimento individual e coletivo | C24: =COUNTA(B24) -> 0 | D24: =Referências!$B$2 -> 1 | E24: =C24*D24 -> 0
A25: Consegue influenciar e orientar as pessoas de maneira moderada, estabelecendo alguns relacionamentos de confiança, mas ainda apresenta dificuldades na comunicação, enfrentando desafios para impulsionar o desenvolvimento individual e coletivo de forma consistente | C25: =COUNTA(B25) -> 0 | D25: =Referências!$B$3 -> 2 | E25: =C25*D25 -> 0
A26: Influencia, inspira e comunica-se com os outros de maneira consistente, estabelecendo relacionamentos de confiança sólidos e orientando pessoas e equipes para atingir objetivos organizacionais e promover o crescimento contínuo | C26: =COUNTA(B26) -> 0 | D26: =Referências!$B$4 -> 3 | E26: =C26*D26 -> 0
A27: Exerce uma influência significativa e inspiradora, guiando pessoas e equipes para alcançar resultados excepcionais, estabelecendo relacionamentos profundos de confiança e promovendo um crescimento contínuo e sustentável para a organização e seus membros | C27: =COUNTA(B27) -> 0 | D27: =Referências!$B$5 -> 5 | E27: =C27*D27 -> 0
E28: =SUM(E24:E27) -> 0
A29: ='Agregados Agro'!F6 -> Orientação para segurança | B29: Avaliação
A30: Capacidade de priorizar a integridade física no ambiente de trabalho, seguindo normas, identificando riscos e adotando comportamentos preventivos para evitar acidentes, envolvendo uma postura ativa na promoção de um ambiente seguro para si e para os demais.
A31: Comportamentos observáveis | C31: =VLOOKUP(A29,'Agregados Agro'!$F$3:$G$12,2,FALSE) -> 0.15 | D31: =COUNTA(A32:A35) -> 4 | E31: =C31*E36 -> 0
A32: Segue as normas de segurança apenas quando exigido, age de forma reativa diante de riscos e não se preocupa em identificar ou relatar potenciais perigos no ambiente de trabalho | C32: =COUNTA(B32) -> 0 | D32: =Referências!$B$2 -> 1 | E32: =C32*D32 -> 0
A33: Adota práticas seguras no dia a dia, respeita normas e sinaliza riscos quando identificados, mas não age proativamente para promover a segurança de forma ampla | C33: =COUNTA(B33) -> 0 | D33: =Referências!$B$3 -> 2 | E33: =C33*D33 -> 0
A34: Além de cumprir as normas, antecipa e reporta riscos, orienta colegas sobre práticas seguras e busca melhorar processos para reduzir acidentes e incidentes | C34: =COUNTA(B34) -> 0 | D34: =Referências!$B$4 -> 3 | E34: =C34*D34 -> 0
A35: Atua como referência em segurança, inspira e orienta os outros, propõe e participa ativamente da implementação de melhorias nos procedimentos e age antecipadamente para eliminar riscos, contribuindo para um ambiente de trabalho mais seguro e preventivo | C35: =COUNTA(B35) -> 0 | D35: =Referências!$B$5 -> 5 | E35: =C35*D35 -> 0
E36: =SUM(E32:E35) -> 0
A37: ='Agregados Agro'!F7 -> Proatividade | B37: Avaliação
A38: Capacidade de agir de forma antecipada e responsável para evitar problemas, melhorar processos, atuando com iniciativa, atenção aos detalhes.
A39: Comportamentos observáveis | C39: =VLOOKUP(A37,'Agregados Agro'!$F$3:$G$12,2,FALSE) -> 0.1 | D39: =COUNTA(A40:A43) -> 4 | E39: =C39*E44 -> 0
A40: Atua apenas quando solicitado, aguarda instruções para iniciar qualquer atividade e não demonstra preocupação em antecipar problemas ou propor melhorias | C40: =COUNTA(B40) -> 0 | D40: =Referências!$B$2 -> 1 | E40: =C40*D40 -> 0
A41: Cumpre suas funções com qualidade e dentro dos prazos, sinaliza problemas à liderança, mas não busca soluções por conta própria, e participa de iniciativas de melhoria quando solicitado | C41: =COUNTA(B41) -> 0 | D41: =Referências!$B$3 -> 2 | E41: =C41*D41 -> 0
...

Sheet Supervisor e Gerente
A2: Grupo funcional: Supervisor e Gerente | D2: Peso total | E2: Pontuação
D3: =SUM(C7,C15,C23,C31,C39,C47) -> 1 | E3: =SUM(E7,E15,E23,E31,E39,E47) -> 0
D4: Resultado
A5: ='Agregados Agro'!H3 -> Eficiência | B5: Avaliação | D5: =IF(E3<=[1]Referências!$B$9,[1]Referências!C9,IF(E3<=[1]Referências!$B$10,[1]Referências!$C$10,IF(E3<=[1]Referências!$B$11,[1]Referências!$C$11,IF(E3<=[1]Referências!$B$12,[1]Referências!$C$12,[1]Referências!$C$13)))) -> Não atende
A6: Capacidade de alcançar os resultados estabelecidos para a organização com o mínimo de recursos possíveis, como tempo, esforço, custo e materiais, realizando as tarefas de maneira otimizada e sem desperdícios
A7: Comportamentos observáveis | C7: =VLOOKUP(A5,'Agregados Agro'!$H$3:$I$12,2,FALSE) -> 0.1 | E7: =C7*E12 -> 0
A8: Realiza ações direcionadas ao cumprimento das metas sem considerar a eficiência no uso de recursos e nem sempre identifica as prioridades ou os impactos nos resultados, necessitando de orientação para alinhar seus esforços aos objetivos organizacionais | C8: =COUNTA(B8) -> 0 | D8: =Referências!$B$2 -> 1 | E8: =C8*D8 -> 0
A9: Direciona seus esforços para ações que impactam diretamente nas metas, mas ainda necessita de apoio para a busca de resultados consistentes e alinhados aos valores e princípios da empresa | C9: =COUNTA(B9) -> 0 | D9: =Referências!$B$3 -> 2 | E9: =C9*D9 -> 0
A10: Planeja e executa ações que potencializam os resultados organizacionais, administrando recursos de maneira eficiente para o alcançar metas de forma consistente, mesmo em situações desafiadoras, realizando entregas com baixo desperdício, dentro dos custos e prazos estabelecidos | C10: =COUNTA(B10) -> 0 | D10: =Referências!$B$4 -> 3 | E10: =C10*D10 -> 0
A11: Concentra esforços em ações de alto impacto, alcançando resultados com o mínimo de recursos e sem desperdícios, atuando de forma exemplar no alcance de resultados e na superação de metas | C11: =COUNTA(B11) -> 0 | D11: =Referências!$B$5 -> 5 | E11: =C11*D11 -> 0
E12: =SUM(E8:E11) -> 0
A13: ='Agregados Agro'!H4 -> Comprometimento | B13: Avaliação
A14: Capacidade de cumprir o planejamento e objetivos organizacionais no curto e médio prazos, conforme normas e procedimentos, demonstrando constância, pontualidade e responsabilidade no alcance dos objetivos setoriais
A15: Comportamentos observáveis | C15: =VLOOKUP(A13,'Agregados Agro'!$H$3:$I$12,2,FALSE) -> 0.2 | D15: =COUNTA(A17:A19) -> 3 | E15: =C15*E20 -> 0
A16: Esforça-se para cumprir o planejamento e os objetivos do setor, mas com frequência precisa de orientações e apoio, apresentando dificuldades em manter a constância e a pontualidade nas entregas | C16: =COUNTA(B16) -> 0 | D16: =Referências!$B$2 -> 1 | E16: =C16*D16 -> 0
A17: Cumpre o planejamento e objetivos do setor de forma regular, apresentando pontualidade e seguindo as normas e procedimentos estabelecidos na maior parte das vezes | C17: =COUNTA(B17) -> 0 | D17: =Referências!$B$3 -> 2 | E17: =C17*D17 -> 0
A18: Cumpre o planejamento e as metas de maneira constante e comprometida, com aderência às normas, procedimentos e padrões, demonstrando responsabilidade e pontualidade nas entregas setoriais | C18: =COUNTA(B18) -> 0 | D18: =Referências!$B$4 -> 3 | E18: =C18*D18 -> 0
A19: Realiza as tarefas de forma exemplar, atuando como modelo de compromisso e responsabilidade, influenciando positivamente os outros ao demonstrar constância, pontualidade e responsabilidade em todas as entregas setoriais | C19: =COUNTA(B19) -> 0 | D19: =Referências!$B$5 -> 5 | E19: =C19*D19 -> 0
E20: =SUM(E16:E19) -> 0
A21: ='Agregados Agro'!H5 -> Gestão de Pessoas | B21: Avaliação
A22: Capacidade de influenciar, inspirar e orientar pessoas e equipes para atingir objetivos organizacionais, estabelecendo relacionamentos de confiança, promovendo o crescimento individual e coletivo
A23: Comportamentos observáveis | C23: =VLOOKUP(A21,'Agregados Agro'!$H$3:$I$12,2,FALSE) -> 0.2 | D23: =COUNTA(A24:A27) -> 4 | E23: =C23*E28 -> 0
A24: Demonstra dificuldades em influenciar e orientar os outros, estabelecendo relacionamentos superficiais ou com pouca confiança mútua devido a dificuldade de se comunicar e administrar conflitos, e requer apoio contínuo nas estratégias de desenvolvimento individual e coletivo | C24: =COUNTA(B24) -> 0 | D24: =Referências!$B$2 -> 1 | E24: =C24*D24 -> 0
A25: Consegue influenciar e orientar as pessoas de maneira moderada, estabelecendo alguns relacionamentos de confiança, mas ainda apresenta dificuldades na comunicação, enfrentando desafios para impulsionar o desenvolvimento individual e coletivo de forma consistente | C25: =COUNTA(B25) -> 0 | D25: =Referências!$B$3 -> 2 | E25: =C25*D25 -> 0
A26: Influencia, inspira e comunica-se com os outros de maneira consistente, estabelecendo relacionamentos de confiança sólidos e orientando pessoas e equipes para atingir objetivos organizacionais e promover o crescimento contínuo | C26: =COUNTA(B26) -> 0 | D26: =Referências!$B$4 -> 3 | E26: =C26*D26 -> 0
A27: Exerce uma influência significativa e inspiradora, guiando pessoas e equipes para alcançar resultados excepcionais, estabelecendo relacionamentos profundos de confiança e promovendo um crescimento contínuo e sustentável para a organização e seus membros | C27: =COUNTA(B27) -> 0 | D27: =Referências!$B$5 -> 5 | E27: =C27*D27 -> 0
E28: =SUM(E24:E27) -> 0
A29: ='Agregados Agro'!H6 -> Orientação para segurança | B29: Avaliação
A30: Capacidade de priorizar a integridade física no ambiente de trabalho, seguindo normas, identificando riscos e adotando comportamentos preventivos para evitar acidentes, envolvendo uma postura ativa na promoção de um ambiente seguro para si e para os demais.
A31: Comportamentos observáveis | C31: =VLOOKUP(A29,'Agregados Agro'!$H$3:$I$12,2,FALSE) -> 0.15 | D31: =COUNTA(A32:A35) -> 4 | E31: =C31*E36 -> 0
A32: Segue as normas de segurança apenas quando exigido, age de forma reativa diante de riscos e não se preocupa em identificar ou relatar potenciais perigos no ambiente de trabalho | C32: =COUNTA(B32) -> 0 | D32: =Referências!$B$2 -> 1 | E32: =C32*D32 -> 0
A33: Adota práticas seguras no dia a dia, respeita normas e sinaliza riscos quando identificados, mas não age proativamente para promover a segurança de forma ampla | C33: =COUNTA(B33) -> 0 | D33: =Referências!$B$3 -> 2 | E33: =C33*D33 -> 0
A34: Além de cumprir as normas, antecipa e reporta riscos, orienta colegas sobre práticas seguras e busca melhorar processos para reduzir acidentes e incidentes | C34: =COUNTA(B34) -> 0 | D34: =Referências!$B$4 -> 3 | E34: =C34*D34 -> 0
A35: Atua como referência em segurança, inspira e orienta os outros, propõe e participa ativamente da implementação de melhorias nos procedimentos e age antecipadamente para eliminar riscos, contribuindo para um ambiente de trabalho mais seguro e preventivo | C35: =COUNTA(B35) -> 0 | D35: =Referências!$B$5 -> 5 | E35: =C35*D35 -> 0
E36: =SUM(E32:E35) -> 0
A37: ='Agregados Agro'!H7 -> Visão sistêmica | B37: Avaliação
A38: Capacidade de visualizar a empresa como um sistema integrado, percebendo a inter-relação e a interdependência das áreas bem como o impacto de suas ações para os resultados do negócio, para os colaboradores e partes interessadas
A39: Comportamentos observáveis | C39: =VLOOKUP(A37,'Agregados Agro'!$H$3:$I$12,2,FALSE) -> 0.15 | D39: =COUNTA(A40:A43) -> 4 | E39: =C39*E44 -> 0
A40: Reconhece que a empresa é composta por diferentes áreas, mas entende superficialmente que as ações de uma área podem afetar outras, apresentando um foco maior nas responsabilidades e metas da própria área | C40: =COUNTA(B40) -> 0 | D40: =Referências!$B$2 -> 1 | E40: =C40*D40 -> 0
A41: Reconhece a inter-relação entre algumas áreas da empresa e demonstra interesse em entender como os processos de diferentes áreas se conectam, apresentando esforços para adaptar ações da sua área de forma a minimizar impactos negativos em outras | C41: =COUNTA(B41) -> 0 | D41: =Referências!$B$3 -> 2 | E41: =C41*D41 -> 0
...

Sheet Diretor
A2: Grupo funcional: Diretor | D2: Peso total | E2: Pontuação
D3: =SUM(C7,C15,C23,C31,C39,C47,C55) -> 1 | E3: =SUM(E7,E15,E23,E31,E39,E47,E55) -> 0
D4: Resultado
A5: ='Agregados Agro'!J3 -> Eficiência | B5: Avaliação | D5: =IF(E3<=[1]Referências!$B$9,[1]Referências!C9,IF(E3<=[1]Referências!$B$10,[1]Referências!$C$10,IF(E3<=[1]Referências!$B$11,[1]Referências!$C$11,IF(E3<=[1]Referências!$B$12,[1]Referências!$C$12,[1]Referências!$C$13)))) -> Não atende
A6: Capacidade de alcançar os resultados estabelecidos para a organização com o mínimo de recursos possíveis, como tempo, esforço, custo e materiais, realizando as tarefas de maneira otimizada e sem desperdícios
A7: Comportamentos observáveis | C7: =VLOOKUP(A5,'Agregados Agro'!$J$3:$K$12,2,FALSE) -> 0.1 | E7: =C7*E12 -> 0
A8: Realiza ações direcionadas ao cumprimento das metas sem considerar a eficiência no uso de recursos e nem sempre identifica as prioridades ou os impactos nos resultados, necessitando de orientação para alinhar seus esforços aos objetivos organizacionais | C8: =COUNTA(B8) -> 0 | D8: =Referências!$B$2 -> 1 | E8: =C8*D8 -> 0
A9: Direciona seus esforços para ações que impactam diretamente nas metas, mas ainda necessita de apoio para a busca de resultados consistentes e alinhados aos valores e princípios da empresa | C9: =COUNTA(B9) -> 0 | D9: =Referências!$B$3 -> 2 | E9: =C9*D9 -> 0
A10: Planeja e executa ações que potencializam os resultados organizacionais, administrando recursos de maneira eficiente para o alcançar metas de forma consistente, mesmo em situações desafiadoras, realizando entregas com baixo desperdício, dentro dos custos e prazos estabelecidos | C10: =COUNTA(B10) -> 0 | D10: =Referências!$B$4 -> 3 | E10: =C10*D10 -> 0
A11: Concentra esforços em ações de alto impacto, alcançando resultados com o mínimo de recursos e sem desperdícios, atuando de forma exemplar no alcance de resultados e na superação de metas | C11: =COUNTA(B11) -> 0 | D11: =Referências!$B$5 -> 5 | E11: =C11*D11 -> 0
E12: =SUM(E8:E11) -> 0
A13: ='Agregados Agro'!J4 -> Comprometimento | B13: Avaliação
A14: Capacidade de cumprir o planejamento e objetivos organizacionais no curto, médio e longo prazos, conforme normas e procedimentos, demonstrando constância, pontualidade e responsabilidade no alcance dos objetivos organizacionais
A15: Comportamentos observáveis | C15: =VLOOKUP(A13,'Agregados Agro'!$J$3:$K$12,2,FALSE) -> 0.1 | D15: =COUNTA(A17:A19) -> 3 | E15: =C15*E20 -> 0
A16: Esforça-se para cumprir o planejamento e os objetivos organizacionais, mas com frequência precisa de orientações e apoio, apresentando dificuldades em manter a constância e a pontualidade nas entregas | C16: =COUNTA(B16) -> 0 | D16: =Referências!$B$2 -> 1 | E16: =C16*D16 -> 0
A17: Cumpre o planejamento e objetivos organizacionais de forma regular, apresentando pontualidade e seguindo as normas e procedimentos estabelecidos na maior parte das vezes | C17: =COUNTA(B17) -> 0 | D17: =Referências!$B$3 -> 2 | E17: =C17*D17 -> 0
A18: Cumpre o planejamento e as metas de maneira constante e comprometida, com aderência às normas, procedimentos e padrões, demonstrando responsabilidade e pontualidade nas entregas | C18: =COUNTA(B18) -> 0 | D18: =Referências!$B$4 -> 3 | E18: =C18*D18 -> 0
A19: Realiza as tarefas de forma exemplar, atuando como modelo de compromisso e responsabilidade, influenciando positivamente os outros ao demonstrar constância, pontualidade e responsabilidade em todas as entregas | C19: =COUNTA(B19) -> 0 | D19: =Referências!$B$5 -> 5 | E19: =C19*D19 -> 0
E20: =SUM(E16:E19) -> 0
A21: ='Agregados Agro'!J5 -> Gestão de Pessoas | B21: Avaliação
A22: Capacidade de influenciar, inspirar e orientar pessoas e equipes para atingir objetivos organizacionais, estabelecendo relacionamentos de confiança, promovendo o crescimento individual e coletivo
A23: Comportamentos observáveis | C23: =VLOOKUP(A21,'Agregados Agro'!$J$3:$K$12,2,FALSE) -> 0.15 | D23: =COUNTA(A24:A27) -> 4 | E23: =C23*E28 -> 0
A24: Demonstra dificuldades em influenciar e orientar os outros, estabelecendo relacionamentos superficiais ou com pouca confiança mútua, e requer apoio contínuo nas estratégias de desenvolvimento individual e coletivo | C24: =COUNTA(B24) -> 0 | D24: =Referências!$B$2 -> 1 | E24: =C24*D24 -> 0
A25: Consegue influenciar e orientar as pessoas de maneira moderada, estabelecendo alguns relacionamentos de confiança, mas ainda enfrenta desafios para impulsionar o desenvolvimento individual e coletivo de forma consistente | C25: =COUNTA(B25) -> 0 | D25: =Referências!$B$3 -> 2 | E25: =C25*D25 -> 0
A26: Influencia e inspira os outros de maneira consistente, estabelece relacionamentos de confiança sólidos e orienta pessoas e equipes para atingir objetivos organizacionais e promover o crescimento contínuo | C26: =COUNTA(B26) -> 0 | D26: =Referências!$B$4 -> 3 | E26: =C26*D26 -> 0
A27: Exerce uma influência significativa e inspiradora, guiando pessoas e equipes para alcançar resultados excepcionais, estabelecendo relacionamentos profundos de confiança e promovendo um crescimento contínuo e sustentável para a organização e seus membros | C27: =COUNTA(B27) -> 0 | D27: =Referências!$B$5 -> 5 | E27: =C27*D27 -> 0
E28: =SUM(E24:E27) -> 0
A29: ='Agregados Agro'!J6 -> Orientação para segurança | B29: Avaliação
A30: Capacidade de priorizar a integridade física no ambiente de trabalho, seguindo normas, identificando riscos e adotando comportamentos preventivos para evitar acidentes, envolvendo uma postura ativa na promoção de um ambiente seguro para si e para os demais.
A31: Comportamentos observáveis | C31: =VLOOKUP(A29,'Agregados Agro'!$J$3:$K$12,2,FALSE) -> 0.1 | D31: =COUNTA(A32:A35) -> 4 | E31: =C31*E36 -> 0
A32: Segue as normas de segurança apenas quando exigido, age de forma reativa diante de riscos e não se preocupa em identificar ou relatar potenciais perigos no ambiente de trabalho | C32: =COUNTA(B32) -> 0 | D32: =Referências!$B$2 -> 1 | E32: =C32*D32 -> 0
A33: Adota práticas seguras no dia a dia, respeita normas e sinaliza riscos quando identificados, mas não age proativamente para promover a segurança de forma ampla | C33: =COUNTA(B33) -> 0 | D33: =Referências!$B$3 -> 2 | E33: =C33*D33 -> 0
A34: Além de cumprir as normas, antecipa e reporta riscos, orienta colegas sobre práticas seguras e busca melhorar processos para reduzir acidentes e incidentes | C34: =COUNTA(B34) -> 0 | D34: =Referências!$B$4 -> 3 | E34: =C34*D34 -> 0
A35: Atua como referência em segurança, inspira e orienta os outros, propõe e participa ativamente da implementação de melhorias nos procedimentos e age antecipadamente para eliminar riscos, contribuindo para um ambiente de trabalho mais seguro e preventivo | C35: =COUNTA(B35) -> 0 | D35: =Referências!$B$5 -> 5 | E35: =C35*D35 -> 0
E36: =SUM(E32:E35) -> 0
A37: ='Agregados Agro'!J7 -> Relacionamento interpessoal | B37: Avaliação
A38: Capacidade de influenciar, inspirar e orientar pessoas para atingir objetivos organizacionais, administrando conflitos e estabelecendo relacionamentos de confiança com colaboradores, comunidade, clientes e fornecedores, contribuindo diretamente para o crescimento organizacional
A39: Comportamentos observáveis | C39: =VLOOKUP(A37,'Agregados Agro'!$J$3:$K$12,2,FALSE) -> 0.2 | D39: =COUNTA(A40:A43) -> 4 | E39: =C39*E44 -> 0
A40: Interage de forma limitada, focando apenas nas próprias responsabilidades, apresentando dificuldade em administrar conflitos, estabelecer conexões de confiança e influenciar no ambiente ao seu redor | C40: =COUNTA(B40) -> 0 | D40: =Referências!$B$2 -> 1 | E40: =C40*D40 -> 0
A41: Mantém boas relações com pessoas, grupos e entidades relacionados à empresa com que atua, comunicando-se de forma respeitosa, administrando conflitos e contribuindo para estabelecer relacionamentos de confiança, mas ainda tem pouca influência sobre os outros | C41: =COUNTA(B41) -> 0 | D41: =Referências!$B$3 -> 2 | E41: =C41*D41 -> 0
...

Sheet Referências
A1: Avaliação | B1: Pontuação
A2: Não atende | B2: 1
A3: Atende parcialmente | B3: 2
A4: Atende | B4: 3
A5: Supera | B5: 5
A7: Pontuação final da avaliação
A8: Referência | C8: Resultado
A9: Igual ou menor que | B9: 1.6 | C9: Não atende
A10: Igual ou menor que | B10: 2.6 | C10: Atende parcialmente | H10: Não atende | N10: Atende parcialmente | X10: Atende | AH10: Supera | AQ10: Supera muito | CN10: Supera muito
A11: Igual ou menor que | B11: 3.6 | C11: Atende | H11: Abaixo do esperado | X11: Dentro do esperado | AH11: Acima do esperado
A12: Igual ou menor que | B12: 4.5 | C12: Supera
A13: Maior que | B13: =B12 -> 4.5 | C13: Supera muito

Sheet Resultado
A1: Resultado consolidado da Avaliação de Desempenho | F1: Pesos
G2: 0.1
A3: Nome do Colaborador | B3: Eixo | C3: Área | D3: Cargo | E3: Nome do avaliador | F3: Nota Gestor | G3: Nota Auto avaliação | H3: Nota final | I3: Resultado final
A4: Exemplo | F4: 2.9 | G4: 4 | H4: =(F4*$F$2)+(G4*$G$2) -> 0.4 | I4: =IF($H4<=Referências!#REF!,Referências!#REF!,IF($H4<=Referências!#REF!,Referências!#REF!,IF($H4<=Referências!#REF!,Referências!#REF!,Referências!#REF!))) -> #REF!
A5: Exemplo | F5: 3.2 | G5: 3.8 | H5: =(F5*$F$2)+(G5*$G$2) -> 0.38 | I5: =IF($H5<=Referências!#REF!,Referências!#REF!,IF($H5<=Referências!#REF!,Referências!#REF!,IF($H5<=Referências!#REF!,Referências!#REF!,Referências!#REF!))) -> #REF!
A6: Exemplo | F6: 4.2 | G6: 4.5 | H6: =(F6*$F$2)+(G6*$G$2) -> 0.45 | I6: =IF($H6<=Referências!#REF!,Referências!#REF!,IF($H6<=Referências!#REF!,Referências!#REF!,IF($H6<=Referências!#REF!,Referências!#REF!,Referências!#REF!))) -> #REF!
A7: Exemplo | F7: 1.5 | G7: 2.8 | H7: =(F7*$F$2)+(G7*$G$2) -> 0.28 | I7: =IF($H7<=Referências!#REF!,Referências!#REF!,IF($H7<=Referências!#REF!,Referências!#REF!,IF($H7<=Referências!#REF!,Referências!#REF!,Referências!#REF!))) -> #REF!
A8: Exemplo | F8: 2.8 | G8: 3.6 | H8: =(F8*$F$2)+(G8*$G$2) -> 0.36 | I8: =IF($H8<=Referências!#REF!,Referências!#REF!,IF($H8<=Referências!#REF!,Referências!#REF!,IF($H8<=Referências!#REF!,Referências!#REF!,Referências!#REF!))) -> #REF!
A9: Exemplo | F9: 3.6 | G9: 4 | H9: =(F9*$F$2)+(G9*$G$2) -> 0.4 | I9: =IF($H9<=Referências!#REF!,Referências!#REF!,IF($H9<=Referências!#REF!,Referências!#REF!,IF($H9<=Referências!#REF!,Referências!#REF!,Referências!#REF!))) -> #REF!
A10: Exemplo | F10: 4 | G10: 4.1 | H10: =(F10*$F$2)+(G10*$G$2) -> 0.41 | I10: =IF($H10<=Referências!#REF!,Referências!#REF!,IF($H10<=Referências!#REF!,Referências!#REF!,IF($H10<=Referências!#REF!,Referências!#REF!,Referências!#REF!))) -> #REF!
A11: Exemplo | F11: 1.8 | G11: 2.3 | H11: =(F11*$F$2)+(G11*$G$2) -> 0.23 | I11: =IF($H11<=Referências!#REF!,Referências!#REF!,IF($H11<=Referências!#REF!,Referências!#REF!,IF($H11<=Referências!#REF!,Referências!#REF!,Referências!#REF!))) -> #REF!
A12: Exemplo | F12: 2.3 | G12: 3.5 | H12: =(F12*$F$2)+(G12*$G$2) -> 0.35 | I12: =IF($H12<=Referências!#REF!,Referências!#REF!,IF($H12<=Referências!#REF!,Referências!#REF!,IF($H12<=Referências!#REF!,Referências!#REF!,Referências!#REF!))) -> #REF!
