Workbook
Name _DAT1: #REF!
Name _DAT1: #REF!
Name _DAT1: #REF!
Name _DAT10: #REF!
Name _DAT10: #REF!
Name _dat105: #REF!
Name _dat105: #REF!
Name _DAT11: #REF!
Name _DAT11: #REF!
Name _DAT12: #REF!
Name _DAT12: #REF!
Name _DAT13: #REF!
Name _DAT13: #REF!
Name _DAT14: #REF!
Name _DAT14: #REF!
Name _DAT15: #REF!
Name _DAT15: #REF!
Name _DAT16: #REF!
Name _DAT16: #REF!
Name _DAT17: #REF!
Name _DAT17: #REF!
Name _DAT18: #REF!
Name _DAT18: #REF!
Name _DAT19: #REF!
Name _DAT19: #REF!
Name _DAT2: #REF!
Name _DAT2: #REF!
Name _DAT20: #REF!
Name _DAT20: #REF!
Name _DAT3: #REF!
Name _DAT3: #REF!
Name _DAT4: #REF!
Name _DAT4: #REF!
Name _DAT5: #REF!
Name _DAT5: #REF!
Name _DAT6: #REF!
Name _DAT6: #REF!
Name _DAT7: #REF!
Name _DAT7: #REF!
Name _DAT8: #REF!
Name _DAT8: #REF!
Name _DAT9: #REF!
Name _DAT9: #REF!
Name ACUMULACAO: #REF!
Name ACUMULACAO: #REF!
Name Administrativo: #REF!
Name Administrativo: #REF!
Name Format2Print: #REF!
Name IDCARGO: #REF!
Name IDCARGO: #REF!
Name IDCARGO: #REF!
Name NP: #REF!
Name NP: #REF!
Name QP: #REF!
Name QP: #REF!
Name TABMOL: #REF!
Name TABMOL: #REF!
Name TEST1: #REF!
Name TEST1: #REF!
Name TEST2: #REF!

Sheet Agro
B1: Operacional | D1: Encarregado | F1: Gerente
B2: Competências | C2: Peso | D2: Competências | E2: Peso | F2: Competências | G2: Peso
A3: 1 | B3: Comprometimento | C3: 0.2 | D3: Capacidade de análise | E3: 0.2 | F3: Gestão de Pessoas | G3: 0.15
A4: 2 | B4: Organização e zelo com equipamentos | C4: 0.25 | D4: Comprometimento | E4: 0.1 | F4: Gestão de recursos | G4: 0.25
A5: 3 | B5: Orientação para segurança | C5: 0.25 | D5: Comunicação | E5: 0.15 | F5: Orientação para resultados | G5: 0.15
A6: 4 | B6: Proatividade | C6: 0.1 | D6: Gestão de Pessoas | E6: 0.2 | F6: Tomada de decisão | G6: 0.25
A7: 5 | B7: Trabalho em equipe | C7: 0.2 | D7: Planejamento | E7: 0.2 | F7: Visão estratégica | G7: 0.2
A8: 6 | D8: Tomada de decisão | E8: 0.15
A9: 7
A10: 8
A11: 9
A12: 10
B13: Soma | C13: =SUM(C3:C12) -> 1 | E13: =SUM(E3:E12) -> 1 | G13: =SUM(G3:G12) -> 1

Sheet Operacional
A2: Grupo funcional: Operacional | D2: Peso total | E2: Pontuação
D3: =SUM(C7,C15,C23,C31,C39) -> 1 | E3: =SUM(E7,E15,E23,E31,E39) -> 0
D4: Resultado
A5: =Agro!B3 -> Comprometimento | B5: Avaliação | D5: =IF(E3<=[1]Referências!$B$9,[1]Referências!C9,IF(E3<=[1]Referências!$B$10,[1]Referências!$C$10,IF(E3<=[1]Referências!$B$11,[1]Referências!$C$11,IF(E3<=[1]Referências!$B$12,[1]Referências!$C$12,[1]Referências!$C$13)))) -> Não atende
A6: Capacidade de cumprir as tarefas conforme normas, procedimentos e prazos estabelecidos, demonstrando constância, pontualidade e disponibilidade
A7: Comportamentos observáveis | C7: =VLOOKUP(A5,Agro!$B$3:$C$12,2,FALSE) -> 0.2 | E7: =C7*E12 -> 0
A8: Apresenta dificuldades em cumprir prazos, normas e procedimentos estabelecidos e a pontualidade e a disponibilidade também são insatisfatórias, o que impacta negativamente na fluidez do trabalho | C8: =COUNTA(B8) -> 0 | D8: =Referências!$B$2 -> 1 | E8: =C8*D8 -> 0
A9: Cumpre prazos, normas e procedimentos em parte das situações, mas a constância nas entregas é instável, e a pontualidade e a disponibilidade oscilam conforme o contexto, exigindo acompanhamento mais próximo | C9: =COUNTA(B9) -> 0 | D9: =Referências!$B$3 -> 2 | E9: =C9*D9 -> 0
A10: Cumpre regularmente os prazos, normas e procedimentos definidos. Apresenta constância nas entregas, com boa organização e responsabilidade. Demonstra pontualidade e está sempre disponível para atender às demandas | C10: =COUNTA(B10) -> 0 | D10: =Referências!$B$4 -> 3 | E10: =C10*D10 -> 0
A11: Atua com elevada constância, demonstrando organização, responsabilidade e proatividade. Cumpre os prazos, é pontual, comprometido e sempre disponível, servindo como referência positiva para a equipe | C11: =COUNTA(B11) -> 0 | D11: =Referências!$B$5 -> 5 | E11: =C11*D11 -> 0
E12: =SUM(E8:E11) -> 0
A13: =Agro!B4 -> Organização e zelo com equipamentos | B13: Avaliação
A14: Realiza suas atribuições de forma ordenada, facilitando e contribuindo para a continuidade e sequência do trabalho, apresentando cuidado na utilização de bens, equipamentos e materiais da empresa
A15: Comportamentos observáveis | C15: =VLOOKUP(A13,Agro!$B$3:$C$12,2,FALSE) -> 0.25 | D15: =COUNTA(A17:A19) -> 3 | E15: =C15*E20 -> 0
A16: O trabalho não é realizado de forma ordenada, reduzindo a produtividade e dificultando a sequência do trabalho por outra pessoa quando necessário, e não zela pela conservação dos equipamentos e materiais sob sua responsabilidade | C16: =COUNTA(B16) -> 0 | D16: =Referências!$B$2 -> 1 | E16: =C16*D16 -> 0
A17: Esforça-se para organizar adequadamente o trabalho e cuidar dos materiais e equipamentos sob sua responsabilidade, mas ainda necessita de orientação e apoio | C17: =COUNTA(B17) -> 0 | D17: =Referências!$B$3 -> 2 | E17: =C17*D17 -> 0
A18: Mantem organizado o seu ambiente de trabalho, planejando suas tarefas sem necessidade de apoio e mantém organizado o ambiente de trabalho e os materiais e equipamentos sob sua responsabilidade | C18: =COUNTA(B18) -> 0 | D18: =Referências!$B$4 -> 3 | E18: =C18*D18 -> 0
A19: Além da elevada organização, antecipa o que precisa ser feito, demonstra flexibilidade em resposta a prioridades e novas solicitações e antecipa o cumprimento de prazos. Materiais e equipamentos sob sua responsabilidade estão sempre com a manutenção em dia, adequadamente conservados e bem organizados. | C19: =COUNTA(B19) -> 0 | D19: =Referências!$B$5 -> 5 | E19: =C19*D19 -> 0
E20: =SUM(E16:E19) -> 0
A21: =Agro!B5 -> Orientação para segurança | B21: Avaliação
A22: Capacidade de priorizar a integridade física no ambiente de trabalho, seguindo normas, identificando riscos e adotando comportamentos preventivos para evitar acidentes, envolvendo uma postura ativa na promoção de um ambiente seguro para si e para os demais.
A23: Comportamentos observáveis | C23: =VLOOKUP(A21,Agro!$B$3:$C$12,2,FALSE) -> 0.25 | D23: =COUNTA(A24:A27) -> 4 | E23: =C23*E28 -> 0
A24: Segue as normas de segurança apenas quando exigido, age de forma reativa diante de riscos e não se preocupa em identificar ou relatar potenciais perigos no ambiente de trabalho | C24: =COUNTA(B24) -> 0 | D24: =Referências!$B$2 -> 1 | E24: =C24*D24 -> 0
A25: Adota práticas seguras no dia a dia, respeita normas e sinaliza riscos quando identificados, mas não age proativamente para promover a segurança de forma ampla | C25: =COUNTA(B25) -> 0 | D25: =Referências!$B$3 -> 2 | E25: =C25*D25 -> 0
A26: Além de cumprir as normas, antecipa e reporta riscos, orienta colegas sobre práticas seguras e busca melhorias contínuas para reduzir acidentes e incidentes | C26: =COUNTA(B26) -> 0 | D26: =Referências!$B$4 -> 3 | E26: =C26*D26 -> 0
A27: Atua como referência em segurança, inspira e orienta os outros, propõe e participa ativamente da implementação de melhorias nos procedimentos e ambientes, e age antecipadamente para eliminar riscos, contribuindo preventivamente para um ambiente de trabalho mais seguro. | C27: =COUNTA(B27) -> 0 | D27: =Referências!$B$5 -> 5 | E27: =C27*D27 -> 0
E28: =SUM(E24:E27) -> 0
A29: =Agro!B6 -> Proatividade | B29: Avaliação
A30: Capacidade de agir de forma antecipada e responsável para evitar problemas, melhorar processos, atuando com iniciativa, atenção aos detalhes.
A31: Comportamentos observáveis | C31: =VLOOKUP(A29,Agro!$B$3:$C$12,2,FALSE) -> 0.1 | D31: =COUNTA(A32:A35) -> 4 | E31: =C31*E36 -> 0
A32: Atua apenas quando solicitado, aguarda instruções para iniciar qualquer atividade e não demonstra preocupação em antecipar problemas ou propor melhorias | C32: =COUNTA(B32) -> 0 | D32: =Referências!$B$2 -> 1 | E32: =C32*D32 -> 0
A33: Cumpre suas funções com qualidade e dentro dos prazos, sinaliza problemas à liderança, mas não busca soluções por conta própria, e participa de iniciativas de melhoria quando solicitado | C33: =COUNTA(B33) -> 0 | D33: =Referências!$B$3 -> 2 | E33: =C33*D33 -> 0
A34: Identifica problemas e propõe soluções antes que impactem o trabalho, busca melhorias para sua rotina e compartilha boas práticas, além de apoiar colegas quando percebe dificuldades | C34: =COUNTA(B34) -> 0 | D34: =Referências!$B$4 -> 3 | E34: =C34*D34 -> 0
A35: Atua como referência para a equipe, inspira colegas a serem mais proativos, antecipa falhas, propõe e participa ativamente da implementação de melhorias | C35: =COUNTA(B35) -> 0 | D35: =Referências!$B$5 -> 5 | E35: =C35*D35 -> 0
E36: =SUM(E32:E35) -> 0
A37: =Agro!B7 -> Trabalho em equipe | B37: Avaliação
A38: Capacidade de agir para o alcance dos objetivos coletivos, demonstrando interesse em compreender as necessidades do outro e contribuir para a criação de soluções conjuntas
A39: Comportamentos observáveis | C39: =VLOOKUP(A37,Agro!$B$3:$C$12,2,FALSE) -> 0.2 | D39: =COUNTA(A40:A43) -> 4 | E39: =C39*E44 -> 0
A40: Demonstra esforço limitado para agir em equipe, apresentando colaboração reativa e geralmente aguardando orientações para contribuir com os objetivos coletivos | C40: =COUNTA(B40) -> 0 | D40: =Referências!$B$2 -> 1 | E40: =C40*D40 -> 0
A41: Busca entender as necessidades dos outros e contribui para soluções coletivas, mas ainda depende de alguma orientação para identificar as melhores formas de colaborar | C41: =COUNTA(B41) -> 0 | D41: =Referências!$B$3 -> 2 | E41: =C41*D41 -> 0
...

Sheet Encarregado
A2: Grupo funcional: Encarregado | D2: Peso total | E2: Pontuação
D3: =SUM(C7,C15,C23,C31,C39,C48) -> 1 | E3: =SUM(E7,E15,E23,E31,E39,E48) -> 0
D4: Resultado
A5: =Agro!D3 -> Capacidade de análise | B5: Avaliação | D5: =IF(E3<=[1]Referências!$B$9,[1]Referências!C9,IF(E3<=[1]Referências!$B$10,[1]Referências!$C$10,IF(E3<=[1]Referências!$B$11,[1]Referências!$C$11,IF(E3<=[1]Referências!$B$12,[1]Referências!$C$12,[1]Referências!$C$13)))) -> Não atende
A6: Capacidade de avaliar informações, situações ou resultados de maneira interpretativa e baseada em dados e argumentos sólidos, extraindo pontos relevantes, convergindo e construindo diagnósticos de forma resumida para resolução de problemas
A7: Comportamentos observáveis | C7: =VLOOKUP(A5,Agro!$D$3:$E$12,2,FALSE) -> 0.2 | E7: =C7*E12 -> 0
A8: Avalia informações e situações de forma superficial, apresentando dificuldades em entender a causa principal dos problemas e sem considerar dados e argumentos sólidos, frequentemente precisando de orientação para identificar pontos relevantes e extrair diagnósticos | C8: =COUNTA(B8) -> 0 | D8: =Referências!$B$2 -> 1 | E8: =C8*D8 -> 0
A9: Realiza avaliações mais fundamentadas, considerando dados e informações, mas ainda com alguma dificuldade em convergir e sintetizar os pontos mais relevantes de maneira clara e concisa e propondo ações genéricas ou não totalmente alinhadas com a situação e que necessitam de ajustes | C9: =COUNTA(B9) -> 0 | D9: =Referências!$B$3 -> 2 | E9: =C9*D9 -> 0
A10: Analisa informações e resultados de maneira interpretativa e organizada, Identificando claramente a raiz do problema, utilizando dados e argumentos consistentes para elaborar diagnósticos claros e objetivos, extraindo os pontos mais relevantes de forma eficiente para implementação de soluções práticas | C10: =COUNTA(B10) -> 0 | D10: =Referências!$B$4 -> 3 | E10: =C10*D10 -> 0
A11: Realiza avaliações complexas e altamente interpretativas, extraindo insights e construindo diagnósticos precisos, com base em dados robustos e argumentos bem fundamentados, apresentando as informações e soluções de forma resumida mas com clareza | C11: =COUNTA(B11) -> 0 | D11: =Referências!$B$5 -> 5 | E11: =C11*D11 -> 0
E12: =SUM(E8:E11) -> 0
A13: =Agro!D4 -> Comprometimento | B13: Avaliação
A14: Capacidade de cumprir as tarefas conforme normas, procedimentos e prazos estabelecidos, demonstrando constância, pontualidade e disponibilidade
A15: Comportamentos observáveis | C15: =VLOOKUP(A13,Agro!$D$3:$E$12,2,FALSE) -> 0.1 | D15: =COUNTA(A17:A19) -> 3 | E15: =C15*E20 -> 0
A16: Apresenta dificuldades em cumprir prazos, normas e procedimentos estabelecidos e a pontualidade e a disponibilidade também são insatisfatórias, o que impacta negativamente na fluidez do trabalho | C16: =COUNTA(B16) -> 0 | D16: =Referências!$B$2 -> 1 | E16: =C16*D16 -> 0
A17: Cumpre prazos, normas e procedimentos em parte das situações, mas a constância nas entregas é instável, e a pontualidade e a disponibilidade oscilam conforme o contexto, exigindo acompanhamento mais próximo | C17: =COUNTA(B17) -> 0 | D17: =Referências!$B$3 -> 2 | E17: =C17*D17 -> 0
A18: Cumpre regularmente os prazos, normas e procedimentos definidos. Apresenta constância nas entregas, com boa organização e responsabilidade. Demonstra pontualidade e está sempre disponível para atender às demandas | C18: =COUNTA(B18) -> 0 | D18: =Referências!$B$4 -> 3 | E18: =C18*D18 -> 0
A19: Atua com elevada constância, demonstrando organização, responsabilidade e proatividade. Cumpre os prazos, é pontual, comprometido e sempre disponível, servindo como referência positiva para a equipe | C19: =COUNTA(B19) -> 0 | D19: =Referências!$B$5 -> 5 | E19: =C19*D19 -> 0
E20: =SUM(E16:E19) -> 0
A21: =Agro!D5 -> Comunicação | B21: Avaliação
A22: Capacidade de interagir com as pessoas, apresentando facilidade para ouvir, processar e compreender a mensagem, transmitindo informações e argumentando com coerência e clareza conforme o público alvo
A23: Comportamentos observáveis | C23: =VLOOKUP(A21,Agro!$D$3:$E$12,2,FALSE) -> 0.15 | D23: =COUNTA(A24:A27) -> 4 | E23: =C23*E28 -> 0
A24: Apresenta dificuldade para estruturar os argumentos e direcionar conversas, deixando a comunicação pouco produtiva, além disso não se certifica do entendimento das partes envolvidas, aumento o risco de falhas na comunicação | C24: =COUNTA(B24) -> 0 | D24: =Referências!$B$2 -> 1 | E24: =C24*D24 -> 0
A25: Na maior parte do tempo comunica-se de modo estruturado, mas pode se perder eventualmente na conversa e fugir do foco, e poucas vezes certifica-se do correto entendimento das partes envolvidas | C25: =COUNTA(B25) -> 0 | D25: =Referências!$B$3 -> 2 | E25: =C25*D25 -> 0
A26: Ouve com atenção e comunica-se de modo estruturado, transmitindo informações com clareza e coerência, certificando-se do correto entendimento das partes envolvidas ao final do processo de comunicação | C26: =COUNTA(B26) -> 0 | D26: =Referências!$B$4 -> 3 | E26: =C26*D26 -> 0
A27: Mantém escuta ativa, interagindo ao longo do diálogo garantindo o adequado entendimento das partes, expressando-se com simplicidade e objetividade, assegurando o correto entendimento das partes envolvidas ao final do processo de comunicação | C27: =COUNTA(B27) -> 0 | D27: =Referências!$B$5 -> 5 | E27: =C27*D27 -> 0
E28: =SUM(E24:E27) -> 0
A29: =Agro!D6 -> Gestão de Pessoas | B29: Avaliação
A30: Capacidade de delegar, influenciar, inspirar e orientar pessoas e equipes para atingir objetivos organizacionais, estabelecendo relacionamentos de confiança, promovendo o crescimento individual e coletivo
A31: Comportamentos observáveis | C31: =VLOOKUP(A29,Agro!$D$3:$E$12,2,FALSE) -> 0.2 | D31: =COUNTA(A32:A35) -> 4 | E31: =C31*E36 -> 0
A32: Demonstra dificuldades em delegar, influenciar e orientar os outros, estabelecendo relacionamentos superficiais ou com pouca confiança mútua, e requer apoio contínuo na gestão de conflitos e estratégias de desenvolvimento individual e coletivo | C32: =COUNTA(B32) -> 0 | D32: =Referências!$B$2 -> 1 | E32: =C32*D32 -> 0
A33: Consegue delegar, influenciar e orientar as pessoas de maneira moderada, estabelecendo alguns relacionamentos de confiança, mas ainda enfrenta desafios para gerir conflitos e impulsionar o desenvolvimento individual e coletivo de forma consistente | C33: =COUNTA(B33) -> 0 | D33: =Referências!$B$3 -> 2 | E33: =C33*D33 -> 0
A34: Delega, influencia e inspira os outros de maneira consistente, estabelece relacionamentos de confiança sólidos e orienta pessoas e equipes para atingir objetivos organizacionais e promover o crescimento contínuo | C34: =COUNTA(B34) -> 0 | D34: =Referências!$B$4 -> 3 | E34: =C34*D34 -> 0
A35: Exerce uma influência significativa e inspiradora, gerindo conflitos e guiando pessoas e equipes para alcançar resultados excepcionais, estabelecendo relacionamentos profundos de confiança e promovendo um crescimento contínuo e sustentável para a organização e seus membros | C35: =COUNTA(B35) -> 0 | D35: =Referências!$B$5 -> 5 | E35: =C35*D35 -> 0
E36: =SUM(E32:E35) -> 0
A37: =Agro!D7 -> Planejamento | B37: Avaliação
A38: Capacidade de definir, organizar e executar ações no curto e médio prazos, garantindo a alocação adequada de recursos, cumprimento de prazos e conclusão das entregas
A39: Comportamentos observáveis | C39: =VLOOKUP(A37,Agro!$D$3:$E$12,2,FALSE) -> 0.2 | D39: =COUNTA(A40:A43) -> 4 | E39: =C39*E44 -> 0
A40: Apresenta dificuldades para definir, organizar e executar ações no curto e médio prazos, resultando em uso inadequado de recursos e frequentes atrasos no cumprimento de prazos e entregas | C40: =COUNTA(B40) -> 0 | D40: =Referências!$B$2 -> 1 | E40: =C40*D40 -> 0
A41: Consegue planejar ações, mas enfrenta desafios na organização e execução, impactando a alocação adequada de recursos e comprometendo, ocasionalmente, o cumprimento de prazos | C41: =COUNTA(B41) -> 0 | D41: =Referências!$B$3 -> 2 | E41: =C41*D41 -> 0
...

Sheet Gerente
A2: Grupo funcional: Gerente | D2: Peso total | E2: Pontuação
D3: =SUM(C7,C15,C23,C31,C39) -> 1 | E3: =SUM(E7,E15,E23,E31,E39) -> 0
D4: Resultado
A5: =Agro!F3 -> Gestão de Pessoas | B5: Avaliação | D5: =IF(E3<=[1]Referências!$B$9,[1]Referências!C9,IF(E3<=[1]Referências!$B$10,[1]Referências!$C$10,IF(E3<=[1]Referências!$B$11,[1]Referências!$C$11,IF(E3<=[1]Referências!$B$12,[1]Referências!$C$12,[1]Referências!$C$13)))) -> Não atende
A6: Capacidade de delegar, influenciar, inspirar e orientar pessoas e equipes para atingir objetivos organizacionais, estabelecendo relacionamentos de confiança, promovendo o crescimento individual e coletivo
A7: Comportamentos observáveis | C7: =VLOOKUP(A5,Agro!$F$3:$G$12,2,FALSE) -> 0.15 | E7: =C7*E12 -> 0
A8: Demonstra dificuldades em delegar, influenciar e orientar os outros, estabelecendo relacionamentos superficiais ou com pouca confiança mútua, e requer apoio contínuo na gestão de conflitos e estratégias de desenvolvimento individual e coletivo | C8: =COUNTA(B8) -> 0 | D8: =Referências!$B$2 -> 1 | E8: =C8*D8 -> 0
A9: Consegue delegar, influenciar e orientar as pessoas de maneira moderada, estabelecendo alguns relacionamentos de confiança, mas ainda enfrenta desafios para gerir conflitos e impulsionar o desenvolvimento individual e coletivo de forma consistente | C9: =COUNTA(B9) -> 0 | D9: =Referências!$B$3 -> 2 | E9: =C9*D9 -> 0
A10: Delega, influencia e inspira os outros de maneira consistente, estabelece relacionamentos de confiança sólidos e orienta pessoas e equipes para atingir objetivos organizacionais e promover o crescimento contínuo | C10: =COUNTA(B10) -> 0 | D10: =Referências!$B$4 -> 3 | E10: =C10*D10 -> 0
A11: Exerce uma influência significativa e inspiradora, gerindo conflitos e guiando pessoas e equipes para alcançar resultados excepcionais, estabelecendo relacionamentos profundos de confiança e promovendo um crescimento contínuo e sustentável para a organização e seus membros | C11: =COUNTA(B11) -> 0 | D11: =Referências!$B$5 -> 5 | E11: =C11*D11 -> 0
E12: =SUM(E8:E11) -> 0
A13: =Agro!F4 -> Gestão de recursos | B13: Avaliação
A14: Capacidade de alocar e otimizar o uso dos recursos disponíveis (humanos, ativos, tecnológicos, materiais, financeiros) garantindo que sejam utilizados de forma eficiente, sustentável e com responsabilidade social e ambiental para maximizar os resultados do negócio
A15: Comportamentos observáveis | C15: =VLOOKUP(A13,Agro!$F$3:$G$12,2,FALSE) -> 0.25 | D15: =COUNTA(A17:A19) -> 3 | E15: =C15*E20 -> 0
A16: Não planeja e utiliza os recursos de forma desorganizada, resultando em desperdícios, baixa produtividade, alocação inadequada de ativos e instabilidade financeira | C16: =COUNTA(B16) -> 0 | D16: =Referências!$B$2 -> 1 | E16: =C16*D16 -> 0
A17: Planeja a aloca os recursos, porém sem visão estratégica, gerando desperdício ou uso inadequado dos recursos, podendo alcançar resultados, mas sem eficiência | C17: =COUNTA(B17) -> 0 | D17: =Referências!$B$3 -> 2 | E17: =C17*D17 -> 0
A18: Gerencia os recursos de forma estruturada e eficiente, garantindo adequada alocação dos recursos, identificando oportunidades de melhoria e ajustando estratégias conforme necessário | C18: =COUNTA(B18) -> 0 | D18: =Referências!$B$4 -> 3 | E18: =C18*D18 -> 0
A19: Atua com excelência na gestão estratégica dos recursos, maximizando a eficiência operacional, reduzindo desperdícios e garantindo investimentos sustentáveis, tornando-se referência na organização | C19: =COUNTA(B19) -> 0 | D19: =Referências!$B$5 -> 5 | E19: =C19*D19 -> 0
E20: =SUM(E16:E19) -> 0
A21: =Agro!F5 -> Orientação para resultados | B21: Avaliação
A22: Capacidade de monitorar e avaliar o desempenho das ações e metas, direcionando esforços para alcançar os objetivos organizacionais
A23: Comportamentos observáveis | C23: =VLOOKUP(A21,Agro!$F$3:$G$12,2,FALSE) -> 0.15 | D23: =COUNTA(A24:A27) -> 4 | E23: =C23*E28 -> 0
A24: Realiza ações direcionadas ao cumprimento dos objetivos, mas não identifica as prioridades ou os impactos nos resultados, enfrentando dificuldade para o cumprimento do planejamento estratégico | C24: =COUNTA(B24) -> 0 | D24: =Referências!$B$2 -> 1 | E24: =C24*D24 -> 0
A25: Direciona esforços para o cumprimento do planejamento estratégico, demonstrando compreensão das prioridades, mas ainda apresenta dificuldades com entregas mais consistentes e alinhadas aos objetivos organizacionais | C25: =COUNTA(B25) -> 0 | D25: =Referências!$B$3 -> 2 | E25: =C25*D25 -> 0
A26: Compreende e define ações para o cumprimento do planejamento estratégico, tomando decisões assertivas para alcançar os objetivos organizacionais | C26: =COUNTA(B26) -> 0 | D26: =Referências!$B$4 -> 3 | E26: =C26*D26 -> 0
A27: Atua de forma exemplar no alcance de resultados e superação de metas, concentrando esforços em ações de alto impacto com eficiência para o cumprimento do planejamento estratégico e alcance dos objetivos organizacionais | C27: =COUNTA(B27) -> 0 | D27: =Referências!$B$5 -> 5 | E27: =C27*D27 -> 0
E28: =SUM(E24:E27) -> 0
A29: =Agro!F6 -> Tomada de decisão | B29: Avaliação
A30: Capacidade de avaliar informações, analisar impactos e escolher a melhor solução para desafios da empresa, considerando regras e objetivos organizacionais para garantir escolhas alinhadas às melhores práticas e resultados esperados para o negócio
A31: Comportamentos observáveis | C31: =VLOOKUP(A29,Agro!$F$3:$G$12,2,FALSE) -> 0.25 | D31: =COUNTA(A32:A35) -> 4 | E31: =C31*E36 -> 0
A32: Evita tomar decisões por conta própria, aguardando orientações mesmo para questões simples, e apresenta dificuldade em avaliar impactos antes de agir | C32: =COUNTA(B32) -> 0 | D32: =Referências!$B$2 -> 1 | E32: =C32*D32 -> 0
A33: Toma decisões em situações rotineiras e previsíveis, seguindo procedimentos estabelecidos, mas ainda depende de orientação em situações mais complexas ou inesperadas | C33: =COUNTA(B33) -> 0 | D33: =Referências!$B$3 -> 2 | E33: =C33*D33 -> 0
A34: Avalia riscos e impactos antes de decidir, busca soluções alinhadas aos objetivos da empresa, consulta informações relevantes e sabe quando envolver outros para garantir uma escolha mais assertiva | C34: =COUNTA(B34) -> 0 | D34: =Referências!$B$4 -> 3 | E34: =C34*D34 -> 0
A35: Toma decisões com autonomia, antecipa problemas e oportunidades, considera impactos a longo prazo e influencia melhorias nos processos decisórios do negócio | C35: =COUNTA(B35) -> 0 | D35: =Referências!$B$5 -> 5 | E35: =C35*D35 -> 0
E36: =SUM(E32:E35) -> 0
A37: =Agro!F7 -> Visão estratégica | B37: Avaliação
A38: Capacidade de compreender o cenário global em que a empresa está inserida, identificar oportunidades e ameaças, antecipar tendências e direcionar ações de longo prazo para alcançar os objetivos organizacionais e contribuir para o melhor direcionamento do negócio
A39: Comportamentos observáveis | C39: =VLOOKUP(A37,Agro!$F$3:$G$12,2,FALSE) -> 0.2 | D39: =COUNTA(A40:A43) -> 4 | E39: =C39*E44 -> 0
A40: Possui foco apenas no presente e nas tarefas imediatas, sem considerar tendências ou o impacto de suas ações no médio e longo prazo, demonstrando dificuldade em compreender como mudanças externas podem afetar a organização | C40: =COUNTA(B40) -> 0 | D40: =Referências!$B$2 -> 1 | E40: =C40*D40 -> 0
A41: Identifica ocasionalmente tendências e desafios que podem impactar a organização, necessitando de orientação para integrar percepções à estratégica do negócio, pois o foco no curto prazo ainda é predominante | C41: =COUNTA(B41) -> 0 | D41: =Referências!$B$3 -> 2 | E41: =C41*D41 -> 0
...

Sheet Referências
A1: Avaliação | B1: Pontuação
A2: Não atende | B2: 1
A3: Atende parcialmente | B3: 2
A4: Atende | B4: 3
A5: Supera | B5: 5
A7: Pontuação final da avaliação
A8: Referência | C8: Resultado
A9: Igual ou menor que | B9: 1.6 | C9: Não atende
A10: Igual ou menor que | B10: 2.6 | C10: Atende parcialmente | H10: Não atende | N10: Atende parcialmente | X10: Atende | AH10: Supera | AQ10: Supera muito | CN10: Supera muito
A11: Igual ou menor que | B11: 3.6 | C11: Atende | H11: Abaixo do esperado | X11: Dentro do esperado | AH11: Acima do esperado
A12: Igual ou menor que | B12: 4.5 | C12: Supera
A13: Maior que | B13: =B12 -> 4.5 | C13: Supera muito

Sheet Resultado
A1: Resultado consolidado da Avaliação de Desempenho | F1: Pesos
G2: 0.1
A3: Nome do Colaborador | B3: Eixo | C3: Área | D3: Cargo | E3: Nome do avaliador | F3: Nota Gestor | G3: Nota Auto avaliação | H3: Nota final | I3: Resultado final
A4: Exemplo | F4: 2.9 | G4: 4 | H4: =(F4*$F$2)+(G4*$G$2) -> 0.4 | I4: =IF($H4<=Referências!#REF!,Referências!#REF!,IF($H4<=Referências!#REF!,Referências!#REF!,IF($H4<=Referências!#REF!,Referências!#REF!,Referências!#REF!))) -> #REF!
A5: Exemplo | F5: 3.2 | G5: 3.8 | H5: =(F5*$F$2)+(G5*$G$2) -> 0.38 | I5: =IF($H5<=Referências!#REF!,Referências!#REF!,IF($H5<=Referências!#REF!,Referências!#REF!,IF($H5<=Referências!#REF!,Referências!#REF!,Referências!#REF!))) -> #REF!
A6: Exemplo | F6: 4.2 | G6: 4.5 | H6: =(F6*$F$2)+(G6*$G$2) -> 0.45 | I6: =IF($H6<=Referências!#REF!,Referências!#REF!,IF($H6<=Referências!#REF!,Referências!#REF!,IF($H6<=Referências!#REF!,Referências!#REF!,Referências!#REF!))) -> #REF!
A7: Exemplo | F7: 1.5 | G7: 2.8 | H7: =(F7*$F$2)+(G7*$G$2) -> 0.28 | I7: =IF($H7<=Referências!#REF!,Referências!#REF!,IF($H7<=Referências!#REF!,Referências!#REF!,IF($H7<=Referências!#REF!,Referências!#REF!,Referências!#REF!))) -> #REF!
A8: Exemplo | F8: 2.8 | G8: 3.6 | H8: =(F8*$F$2)+(G8*$G$2) -> 0.36 | I8: =IF($H8<=Referências!#REF!,Referências!#REF!,IF($H8<=Referências!#REF!,Referências!#REF!,IF($H8<=Referências!#REF!,Referências!#REF!,Referências!#REF!))) -> #REF!
A9: Exemplo | F9: 3.6 | G9: 4 | H9: =(F9*$F$2)+(G9*$G$2) -> 0.4 | I9: =IF($H9<=Referências!#REF!,Referências!#REF!,IF($H9<=Referências!#REF!,Referências!#REF!,IF($H9<=Referências!#REF!,Referências!#REF!,Referências!#REF!))) -> #REF!
A10: Exemplo | F10: 4 | G10: 4.1 | H10: =(F10*$F$2)+(G10*$G$2) -> 0.41 | I10: =IF($H10<=Referências!#REF!,Referências!#REF!,IF($H10<=Referências!#REF!,Referências!#REF!,IF($H10<=Referências!#REF!,Referências!#REF!,Referências!#REF!))) -> #REF!
A11: Exemplo | F11: 1.8 | G11: 2.3 | H11: =(F11*$F$2)+(G11*$G$2) -> 0.23 | I11: =IF($H11<=Referências!#REF!,Referências!#REF!,IF($H11<=Referências!#REF!,Referências!#REF!,IF($H11<=Referências!#REF!,Referências!#REF!,Referências!#REF!))) -> #REF!
A12: Exemplo | F12: 2.3 | G12: 3.5 | H12: =(F12*$F$2)+(G12*$G$2) -> 0.35 | I12: =IF($H12<=Referências!#REF!,Referências!#REF!,IF($H12<=Referências!#REF!,Referências!#REF!,IF($H12<=Referências!#REF!,Referências!#REF!,Referências!#REF!))) -> #REF!
